Workbook

Sheet KPI Dashboard
A1: Healthy4U
A2: KPI DASHBOARD
A3: Ключевые показатели эффективности
A5: 📊 REVENUE METRICS
A6: MRR (Monthly Recurring Revenue) | B6: =SUM('Monthly forecast'!$D$4:$CW$4) | C6: Ежемесячная регулярная выручка
A7: ARR (Annual Recurring Revenue) | B7: =B6*12 | C7: Годовая регулярная выручка
A8: Revenue Growth Rate (MoM) | B8: =(B6-B6)/B6 | C8: Рост выручки месяц к месяцу
A9: Cumulative Revenue | B9: =SUM('Monthly forecast'!$D$4:$CW$4) | C9: Суммарная выручка за все время
A11: 👥 CUSTOMER METRICS
A12: Total Customers | B12: =COUNTA('Unit economics'!$D$6:$CW$6) | C12: Всего активных клиентов
A13: New Customers (Last Month) | B13: =B12 | C13: Новых клиентов за последний месяц
A14: Monthly Churn Rate | B14: =15% | C14: Процент ушедших клиентов в месяц
A15: Customer Lifetime (months) | B15: =1/B14 | C15: Средняя продолжительность подписки
A16: ARPPU (Avg Revenue Per User) | B16: =$100 | C16: Средний доход на пользователя
A18: 💰 UNIT ECONOMICS
A19: LTV (Lifetime Value) | B19: ='Unit economics'!D54 | C19: Пожизненная ценность клиента
A20: CAC (Customer Acquisition Cost) | B20: ='Unit economics'!D59 | C20: Стоимость привлечения клиента
A21: LTV:CAC Ratio | B21: =B19/B20 | C21: Соотношение LTV к CAC (цель: 3-5)
A22: CAC Payback Period (months) | B22: =B20/B16 | C22: Срок окупаемости затрат на привлечение
A23: LTV 12 month | B23: ='Unit economics'!D57 | C23: LTV за 12 месяцев
A25: 💵 FINANCIAL HEALTH
A26: Monthly Burn Rate | B26: =SUM('P&L | Cash Flow | Balance'!D20:D60) | C26: Ежемесячный расход денег
A27: Cash Balance | B27: ='P&L | Cash Flow | Balance'!D70 | C27: Текущий остаток денег
A28: Runway (months) | B28: =B27/B26 | C28: Сколько месяцев работы до конца денег
A29: Gross Margin % | B29: =80% | C29: Валовая маржа (типично для SaaS)
A31: 🎯 BENCHMARKS (B2B SaaS)
A32: LTV:CAC Target (B2B SaaS) | B32: 4:1 | C32: Здоровое соотношение для роста
A33: CAC Payback Target | B33: < 12 months | C33: Рекомендуемый срок окупаемости
A34: Monthly Churn Target (B2B) | B34: < 1% | C34: Целевой показатель оттока
A35: MRR Growth Target | B35: > 10% MoM | C35: Целевой рост для раннего этапа
A37: ⚠️ ВАЖНЫЕ ЗАМЕЧАНИЯ
A38: • Churn 15% в месяц слишком высок для B2B (норма <1%)
A39: • Проверьте: это месячный или годовой churn?
A40: • При корректном churn (1%) LTV вырастет в 15 раз!
A41: • Уточните pricing: $100 за сотрудника или за компанию?

Sheet Scenarios
A1: Healthy4U
A2: СЦЕНАРНОЕ ПЛАНИРОВАНИЕ
A3: Прогнозы развития бизнеса на 24 месяца
A5: ОПИСАНИЕ СЦЕНАРИЕВ
A6: Base Case (Базовый) | B6: Наиболее вероятный сценарий развития
A7: Best Case (Оптимистичный) | B7: Благоприятное развитие событий, быстрый рост
A8: Worst Case (Пессимистичный) | B8: Неблагоприятные условия, медленный рост
A10: КЛЮЧЕВЫЕ ПАРАМЕТРЫ СЦЕНАРИЕВ
A11: Параметр | B11: Base Case | C11: Best Case | D11: Worst Case
A12: 📈 Customer Growth
A13: Monthly New Customers (Month 1-6) | B13: 50 | C13: 80 | D13: 30
A14: Monthly New Customers (Month 7-12) | B14: 100 | C14: 150 | D14: 60
A15: Monthly New Customers (Month 13-24) | B15: 150 | C15: 250 | D15: 80
A17: 💸 Churn Rate
A18: Monthly Churn % | B18: 1.0% | C18: 0.5% | D18: 2.0%
A19: Annual Churn % | B19: 12% | C19: 6% | D19: 24%
A21: 💰 Unit Economics
A22: ARPPU ($/month) | B22: $100 | C22: $120 | D22: $80
A23: CAC ($) | B23: $150 | C23: $120 | D23: $180
A24: LTV:CAC Ratio | B24: 4.0x | C24: 6.0x | D24: 2.7x
A26: 🎯 Market & Growth
A27: Market Penetration (Year 2) | B27: 5% | C27: 10% | D27: 2%
A28: Revenue Growth (MoM avg) | B28: 15% | C28: 25% | D28: 8%
A29: Team Growth (by Month 24) | B29: +30 people | C29: +50 people | D29: +15 people
A31: 💵 Financial
A32: Gross Margin | B32: 80% | C32: 85% | D32: 75%
A33: Operating Expenses Growth | B33: Умеренный | C33: Агрессивный | D33: Консервативный
A34: Break-even Month | B34: Month 18 | C34: Month 12 | D34: Month 24+
A36: ПРОГНОЗНЫЕ МЕТРИКИ НА 24 МЕСЯЦА
A37: Метрика | B37: Base Case | C37: Best Case | D37: Worst Case
A38: После 12 месяцев:
A39: Total Customers | B39: 600 | C39: 960 | D39: 360
A40: MRR | B40: $60,000 | C40: $115,200 | D40: $28,800
A41: ARR | B41: $720,000 | C41: $1,382,400 | D41: $345,600
A42: Cumulative Revenue | B42: $420,000 | C42: $720,000 | D42: $210,000
A44: После 24 месяцев:
A45: Total Customers | B45: 2,100 | C45: 4,200 | D45: 1,200
A46: MRR | B46: $210,000 | C46: $504,000 | D46: $96,000
A47: ARR | B47: $2,520,000 | C47: $6,048,000 | D47: $1,152,000
A48: Cumulative Revenue | B48: $1,890,000 | C48: $3,780,000 | D48: $756,000
...

Sheet Assumptions
A1: Healthy4U
A2: KEY ASSUMPTIONS
A3: Обоснование всех предположений финансовой модели
A5: ⚠️ ВАЖНО: Мы pre-revenue стартап. Все финансовые прогнозы основаны на предположениях ниже.
A7: Параметр | B7: Значение/Диапазон | C7: Источник обоснования | D7: Confidence | E7: Как валидируем
A8: PRICING & REVENUE
A9: ARPPU (Average Revenue Per User) | B9: $100/month | C9: Опрос 15 клиник: 80% готовы платить $80-120. Аналоги: $70-150. Экономия для клиники: $500/мес → наша цена = 20% от экономии (типично для B2B SaaS) | D9: Medium | E9: A/B тест pricing в первых 10 продажах. Интервью после каждой продажи
A10: Tier Adoption | B10: Basic: 70%, Premium: 30% | C10: Assumption на основе B2B SaaS benchmarks. В пилоте все используют "базовый" функционал | D10: Low | E10: Отслеживание feature usage. Предложение premium после 3 месяцев использования
A11: Upsell Growth | B11: $100 → $120 → $150 (over 24 months) | C11: Запланированные premium features. Benchmark: SaaS ARPPU растёт 15-25% годовых при successful upsell | D11: Low | E11: Quarterly upsell campaigns. Tracking conversion to premium tier
A13: CUSTOMER ACQUISITION
A14: Sales Cycle Length | B14: 45 days (1.5 months) | C14: Healthcare procurement research + опыт пилота (2 месяца, но это было без urgency). B2B healthcare: 30-90 дней | D14: Medium | E14: Tracking каждой сделки: первый контакт → close. Цель: сократить до 30 дней
A15: Lead → Demo Conversion | B15: 20% | C15: Industry benchmark для outbound B2B SaaS: 15-25%. Пилот показал высокий интерес, используем mid-point | D15: Medium | E15: Weekly tracking conversion rates по каналам. Оптимизация worst performers
A16: Demo → Customer Conversion | B16: 20% | C16: B2B SaaS benchmark: 15-30%. У нас strong product (пилот NPS 8/10) → используем 20% | D16: Medium | E16: Анализ каждой lost deal. Improve sales materials. Target: 25% к M6
A17: Sales Rep Capacity | B17: 2-3 customers/month | C17: Расчёт: 30 calls/day × 20 days = 600 calls/month → 120 connects → 24 meetings → 5 demos → 1-2 closes. First rep: консервативно 2/month, scaling to 3 | D17: Medium | E17: Weekly sales metrics. После 3 месяцев: adjust targets на основе actual data
A18: CAC Target | B18: $150 (long-term) | C18: Расчёт от LTV:CAC = 4:1. LTV ~$10k (при 1% churn) → CAC = $2.5k / 4 = $625. Но мы aggressive target $150 через product-led growth + content | D18: Low | E18: Monthly CAC tracking. В первые 6 месяцев ожидаем $500-1000. Оптимизация каналов
A20: RETENTION & CHURN
A21: Monthly Churn Rate | B21: 1% (12% annual) | C21: B2B healthcare SaaS benchmark: 0.4-0.8% monthly. Используем 1% консервативно. НЕТ ДАННЫХ - пилот бесплатный | D21: Low | E21: Cohort analysis с первого paying customer. Surveys при cancellation. Target: <0.7% к M12
A22: Customer Lifetime | B22: 100 months (~8 years) | C22: Расчёт: 1 / 0.01 churn = 100 месяцев. Для B2B с годовыми контрактами - realistic | D22: Low | E22: Tracking retention by cohort. Contract renewal rates. Churn reasons analysis
A23: Contract Type | B23: Annual (80%), Monthly (20%) | C23: Healthcare предпочитает предсказуемость → годовые контракты. Но даём опцию monthly для малых клиник | D23: Medium | E23: First 20 sales: предлагаем оба варианта, смотрим preference
A25: MARKET & GROWTH
A26: Total Addressable Market | B26: 50,000 клиник в target regions | C26: Market research: [конкретный источник]. Фокус на клиники 20-200 сотрудников | D26: High | E26: Уже validated через desk research. Ongoing: сегментация рынка
A27: Serviceable Market (5 years) | B27: 5,000 клиник (10% TAM) | C27: Realistic penetration для B2B SaaS в niche. Top competitors имеют 2-5% market share | D27: Medium | E27: Track market share quarterly. Competitive analysis
A28: Year 1 Target | B28: 100 клиник (2% of SAM) | C28: Conservative first year target. Proof of GTM motion before aggressive scaling | D28: Medium | E28: Monthly tracking vs. target. Quarterly plan adjustments
A29: Adoption Rate within Clinic | B29: 70% of staff | C29: Пилот показал 75% adoption (15/20). Используем 70% для paying customers (может быть ниже сопротивление) | D29: High | E29: Track actual adoption in first 10 clinics. Improve onboarding based on data
A31: OPERATIONAL
A32: Onboarding Time | B32: 2 weeks | C32: Пилот: 2 недели от договора до first value. Includes training, integration, setup | D32: High | E32: Already validated. Track time-to-value for each customer. Target: 1 week
A33: Support Load | B33: 2-3 tickets/month/customer | C33: Пилот: 2-3 support requests в месяц. Low-touch product → low support needs | D33: High | E33: Track support metrics. Build knowledge base to reduce tickets
A34: Gross Margin | B34: 80% | C34: Typical SaaS gross margin: 70-85%. Costs: servers, support. High margin business | D34: High | E34: Track actual costs. Should improve to 85%+ at scale
A36: TEAM & SCALING
A37: Sales Hire Timeline | B37: 1 rep at M0, +1 at M6, +1 at M12 | C37: Start with 1 rep to validate sales process. Scale when proven (>10 customers) | D37: High | E37: Hire when: previous rep consistently hits 3 customers/month for 2 months
A38: Payback Period | B38: < 12 months | C38: Target: CAC payback in <12 months. At $150 CAC and $100 MRR = 1.5 months. Comfortable! | D38: Low | E38: Monthly calculation. Adjust marketing if payback > 12 months
A41: CONFIDENCE LEVELS
A42: High | B42: Данные из пилота или подтверждённые исследования
A43: Medium | B43: Индустриальные бенчмарки или обоснованные estimates
A44: Low | B44: Educated guesses - будут validated в первые 6-12 месяцев
A47: 📅 ПЛАН ОБНОВЛЕНИЯ ASSUMPTIONS
A48: Месяц 1-3: Validate pricing, sales cycle, conversion rates с первыми 5 клиентами
A49: Месяц 3-6: Update CAC на основе actual marketing spend и conversions
A50: Месяц 6-12: Начинаем видеть early churn data, корректируем LTV assumptions
A51: Месяц 12+: Mature data, можем строить predictive models
...

Sheet Description
B1: Сайт: | C1: https://anastasianikolaeva.com/ | D1: Телеграм: | E1: https://t.me/anikolayeva
C2: Материалы этого файла могут быть использованы только лицом, купившим данный материал на сайте https://anastasianikolaeva.com/, в целях индивидуального обучения и развития своих бизнес-проектов. Массовое распространение данного материала, продажа и передача 3м лицам являются нарушением авторского права. Если вы хотите порекомендовать материалы своим коллегам, партнерам и друзьям, поделитесь ссылкой на сайт: https://anastasianikolaeva.com/
B3: Если вы хотите получить консультацию или заказать разработку финансовой модели для вашей компании, запишитесь на пробную бесплатную консультацию здесь: https://anastasianikolaeva.com/#expressform
B4: Финансовая модель
B6: Данный шаблон разработан для прогнозирования доходов и расходов компании, продающей цифровые решения по модели "Подписка". Мы рассматриваем 3 потока дохода, которые основаны на способе привлечения клиентов: наиболее популярных способа монетизации для такого продукта: "Самостоятельное приобретение подписки", "Входящие продажи" и "Исходящие продажи". Эта финансовая модель позволяет спрогнозировать точку безубыточности и оценить сумму необходимых инвестиций. Модель автоматически рассчитывает прогноз для вашего бизнеса во вкладках "Monthly forecast", "P&L | Cash Flow | Balance", "Unit Economics" и визуализирует их в "Charts" "For Pitchdeck" на основании данных, введенных на вкладках "Settings", "Roadmap", "Payroll", "Projections".
B9: Инструкции
B11: 1000 | D11: Синим шрифтом выделены поля, куда вносятся данные.
B12: 2000 | D12: Черным шрифтом выделены поля, в которых вычисления производятся по формулам.
B13: Incorporation | D13: В выпадающих списках заданы списки параметров, выбор которых влияет на расчеты в модели.
B14: Вкладка "Setting" | D14: В этой вкладке задаются общие параметры бизнеса. На основании указанных здесь налоговых ставок рассчитывается налог на прибыль во вкладке "P&L and Cash Flow" и налог на заработную плату во вкладке "Payroll".
B15: Вкладка "Roadmap" | D15: В этой вкладке перечисляются события дорожной карты бизнеса, которые будут влиять на динамику доходов и расходов компании. Здесь нужно перечислить такие события и указать их плановые даты. Даты можно задать, указав, через сколько месяцев после привлечения инвестиций произойдет событие. Перечисленные в этой вкладке события попадают в выпадающие списки на вкладках "Payroll" и "Projections". Благодаря этому вы можете привязывать появление новых затрат или доходов и найм определенных сотрудников к событиям в вашей дорожной карте. В зависимости от выбранного события во вкладках "Payroll" и "Projections" автоматически проставляются даты, начиная с которых возникают отдельные доходы и расходы, а во вкладке "Monthly Forecast" начинают учитываться эти данные с нужного месяца.
B16: Вкладка "Payroll" | D16: В этой вкладке вносятся все позиции наемных сотрудников, которые неоходимы вашему бизнесу, их зарплаты, события, при которых они нанимаются, и динамика увеличения зарплат. Здесь нужно внести названия должностей, размер зарплат, выбрать событие из дорожной карты, при котором происходит найм, указать планируемый процент ежегодного увеличения зарплат. Общие затраты на сотрудника с учетом налогов рассчитаются на основании ставки, указанной в "Settings", даты найма проставятся из "Roadmap" на основании выбранного события.
B17: Вкладка "Projections" | D17: В этой вкладке вносятся вводные данные для формирования всех потоков доходов и расходов. Здесь перечисляются все статьи доходов и расходов, задаются их значения, стартовые даты, периодичность и методы расчета динамики. При этом начало возникновения различных статей доходов и расходов связано с событиями дорожной карты, а генерация доходов зависит от прямых расходов, приводящих к продажам. На основании внесенных здесь значений формируется прогноз во вкладке "Monthly forecast".
B18: Вкладка "Monthly Forecast" | D18: В этой вкладке формируется подробный финансовый прогноз бизнеса по месяцам. Все расчеты производятся на основании данных, внесенных во вкладки "Settings", "Roadmap", "Payroll", "Projections" по заданным формулам. В этой вкладке ничего вносить не нужно.
B19: Вкладка "Unit Economics" | D19: В этой вкладке формируется расчет юнит экономики отдельно для каждого варианта монетизации. Расчитывается LTV продукта, CAC (стоимость привлечения клиента), отношение LTV к CAC.
B20: Вкладка "P&L and Cash Flow" | D20: В этой вкладке формируются финансовые отчеты P&L (Прибыли и убытки) и Cash Flow (Денежный поток) по месяцам. Все расчеты производятся на основании данных вкладки "Monthly forecast" по заданным формулам. В этой вкладке ничего вносить не нужно.
B21: Вкладка "For Pitchdeck" | D21: В этой вкладке формируется таблица с динамикой выручки, операционной прибыли (EBITDA) и чистой прибыли по годам и строятся графики для лаконичной визуализации. Таблицу и график из этой вкладки можно скопировать на слайд с финансовой информацией питчдека вашего проекта для презентации инвесторам и партнерам.
B22: Вкладка "Cap Table" | D22: В этой вкладке вносится информация о всех держателях акций компании, привлеченных инвестициях по раундам, планируемой оценке стоимости компании и рассчитываются доли всех участников в динамике по раундам.
B23: Вкладка "Dividends" | D23: В этой вкладке рассчитываются начисленные дивиденды по годам для всех держателей акций компании исходя из прогнозируемой чистой прибыли в соответствии с долями, указанными на вкладке "Cap Table".
B24: Вкладка "Exit scenarios" | D24: В этой вкладке описывается предполагаемый сценарий выхода из компании (как пример приводится продажа компании в виде стратегического поглощения), задается планируемая стоимость продажи компании и предполагаемый год сделки. Рассчитывается доход каждого владельца акций компании при условии продажи всех акции, сумма вложенных инвестиций и ROI при выходе.
... B26: Вкладка "Data for Charts" | D26: Вспомогательная вкладка для упрощения создания графиков для вкладки "Charts". Вынесение данных, для которых необходима визуализация, на отдельную вкладку, помогает избежать ошибок и сделать модель понятнее как для команды проекта, так и для внешних партнеров (например, инвесторов). Все данные расчитываются по формулам на основании остальных вкладок. При необходимости, вы можете вынести сюда и другие метрики, по которым хотите постоить дополнительные графики для вашего бизнеса.

Sheet Settings
A2: GENERAL SETTINGS
A4: Company name | B4: Healthy4U
A5: Currency | B5: USD
A6: Country of incorporation | B6: Israel
A7: Income tax rate | B7: 0.23
A8: Payroll tax rate | B8: 0.35
A9: Tax Payment Month | B9: 3
A10: Cash in bank at start | B10: 0

Sheet Roadmap
A1: =Settings!$B$4
A2: ROADMAP
A4: Growth driving events
B6: Type | C6: Date | D6: Months after seed round
A7: Incorporation | B7: incorporation | C7: 45139 | D7: 0
A8: B2B solution: MVP release | B8: new product | C8: 45884 | D8: 0
A9: B2B solution: 5 clients | B9: monetization | C9: 45899 | D9: 0
A10: Pre-seed round money transfer | B10: fundraising | C10: 45901 | D10: 0
A11: B2B solution: v.1 release | B11: new feature | C11: =if(D11>0,EDATE($C$10,D11),"not set") | D11: 2
A12: Android App for B2B | B12: new feature | C12: =if(D12>0,EDATE($C$11,D12),"not set") | D12: 4
A13: B2B solution: 50 clients | B13: monetization | C13: =if(D13>0,EDATE($C$11,D13),"not set") | D13: 6
A14: B2B solution: 100 clients | B14: fundraising | C14: =if(D14>0,EDATE($C$11,D14),"not set") | D14: 9
A15: Seed round money transfer | B15: fundraising | C15: =if(D15>0,EDATE($C$11,D15),"not set") | D15: 10
A16: EU expansion | B16: new region | C16: =if(D16>0,EDATE($C$11,D16),"not set") | D16: 12

Sheet Payroll
A1: =Settings!$B$4
A2: PAYROLL
D4: Monthly salary | E4: Payroll taxes | F4: Monthly cost to company | G4: Annaul salary | H4: Start event in the roadmap | I4: Hire date | J4: Annual salary increase
A5: Administrative
A6: CEO | D6: 5000 | E6: =Settings!$B$8 | F6: =D6/(1-E6) | G6: =D6*12 | H6: Pre-seed round money transfer | I6: =IFERROR(VLOOKUP(H6,Roadmap!$A$7:$D$110,3,0),"not set, choose the event") | J6: 0.02 | K6: 12
A7: CFO | D7: 0 | E7: =Settings!$B$8 | F7: =D7/(1-E7) | G7: =D7*12 | H7: B2B solution: 5 clients | I7: =IFERROR(VLOOKUP(H7,Roadmap!$A$7:$D$110,3,0),"not set, choose the event") | J7: 0 | K7: 12
A8: COO | D8: 0 | E8: =Settings!$B$8 | F8: =D8/(1-E8) | G8: =D8*12 | H8: B2B solution: 100 clients | I8: =IFERROR(VLOOKUP(H8,Roadmap!$A$7:$D$110,3,0),"not set, choose the event") | J8: 0 | K8: 12
A9: HRD | D9: 0 | E9: =Settings!$B$8 | F9: =D9/(1-E9) | G9: =D9*12 | I9: =IFERROR(VLOOKUP(H9,Roadmap!$A$7:$D$110,3,0),"not set, choose the event") | J9: 0 | K9: 12
A10: Operations Coordinator / Office Manager | D10: 0 | E10: =Settings!$B$8 | F10: =D10/(1-E10) | G10: =D10*12 | I10: =IFERROR(VLOOKUP(H10,Roadmap!$A$7:$D$110,3,0),"not set, choose the event") | J10: 0 | K10: 12
A11: Employee 1 | D11: 0 | E11: =Settings!$B$8 | F11: =D11/(1-E11) | G11: =D11*12 | I11: =IFERROR(VLOOKUP(H11,Roadmap!$A$7:$D$110,3,0),"not set, choose the event") | J11: 0 | K11: 12
A12: Employee 2 | D12: 0 | E12: =Settings!$B$8 | F12: =D12/(1-E12) | G12: =D12*12 | I12: =IFERROR(VLOOKUP(H12,Roadmap!$A$7:$D$110,3,0),"not set, choose the event") | J12: 0 | K12: 12
A13: Employee 3 | D13: 0 | E13: =Settings!$B$8 | F13: =D13/(1-E13) | G13: =D13*12 | I13: =IFERROR(VLOOKUP(H13,Roadmap!$A$7:$D$110,3,0),"not set, choose the event") | J13: 0 | K13: 12
A14: Employee 4 | D14: 0 | E14: =Settings!$B$8 | F14: =D14/(1-E14) | G14: =D14*12 | I14: =IFERROR(VLOOKUP(H14,Roadmap!$A$7:$D$110,3,0),"not set, choose the event") | J14: 0 | K14: 12
A16: IT
A17: CTO | D17: 10000 | E17: =Settings!$B$8 | F17: =D17/(1-E17) | G17: =D17*12 | H17: Seed round money transfer | I17: =IFERROR(VLOOKUP(H17,Roadmap!$A$7:$D$110,3,0),"not set, choose the event") | J17: 0 | K17: 12
A18: Developer frontend | D18: 4000 | E18: =Settings!$B$8 | F18: =D18/(1-E18) | G18: =D18*12 | H18: Seed round money transfer | I18: =IFERROR(VLOOKUP(H18,Roadmap!$A$7:$D$110,3,0),"not set, choose the event") | J18: 0.04 | K18: 12
A19: Developer backend | D19: 0 | E19: =Settings!$B$8 | F19: =D19/(1-E19) | G19: =D19*12 | I19: =IFERROR(VLOOKUP(H19,Roadmap!$A$7:$D$110,3,0),"not set, choose the event") | J19: 0 | K19: 12
A20: Developer fullstack | D20: 0 | E20: =Settings!$B$8 | F20: =D20/(1-E20) | G20: =D20*12 | I20: =IFERROR(VLOOKUP(H20,Roadmap!$A$7:$D$110,3,0),"not set, choose the event") | J20: 0 | K20: 12
A21: UX designer | D21: 3500 | E21: =Settings!$B$8 | F21: =D21/(1-E21) | G21: =D21*12 | I21: =IFERROR(VLOOKUP(H21,Roadmap!$A$7:$D$110,3,0),"not set, choose the event") | J21: 0 | K21: 12
A22: Product manager | D22: 0 | E22: =Settings!$B$8 | F22: =D22/(1-E22) | G22: =D22*12 | I22: =IFERROR(VLOOKUP(H22,Roadmap!$A$7:$D$110,3,0),"not set, choose the event") | J22: 0 | K22: 12
A23: DevOps | D23: 0 | E23: =Settings!$B$8 | F23: =D23/(1-E23) | G23: =D23*12 | I23: =IFERROR(VLOOKUP(H23,Roadmap!$A$7:$D$110,3,0),"not set, choose the event") | J23: 0 | K23: 12
A24: Project Manager | D24: 0 | E24: =Settings!$B$8 | F24: =D24/(1-E24) | G24: =D24*12 | I24: =IFERROR(VLOOKUP(H24,Roadmap!$A$7:$D$110,3,0),"not set, choose the event") | J24: 0 | K24: 12
A25: Developer cross-platform | D25: 0 | E25: =Settings!$B$8 | F25: =D25/(1-E25) | G25: =D25*12 | I25: =IFERROR(VLOOKUP(H25,Roadmap!$A$7:$D$110,3,0),"not set, choose the event") | J25: 0 | K25: 12
A26: QA | D26: 0 | E26: =Settings!$B$8 | F26: =D26/(1-E26) | G26: =D26*12 | I26: =IFERROR(VLOOKUP(H26,Roadmap!$A$7:$D$110,3,0),"not set, choose the event") | J26: 0 | K26: 12
A27: Security engineer | D27: 0 | E27: =Settings!$B$8 | F27: =D27/(1-E27) | G27: =D27*12 | I27: =IFERROR(VLOOKUP(H27,Roadmap!$A$7:$D$110,3,0),"not set, choose the event") | J27: 0 | K27: 12
A28: Employee 4 | D28: 0 | E28: =Settings!$B$8 | F28: =D28/(1-E28) | G28: =D28*12 | I28: =IFERROR(VLOOKUP(H28,Roadmap!$A$7:$D$110,3,0),"not set, choose the event") | J28: 0 | K28: 12
A30: Marketing
A31: Head of Marketing | D31: 3000 | E31: =Settings!$B$8 | F31: =D31/(1-E31) | G31: =D31*12 | H31: Seed round money transfer | I31: =IFERROR(VLOOKUP(H31,Roadmap!$A$7:$D$110,3,0),"not set, choose the event") | J31: 0.04 | K31: 12
A32: Content Marketing Manager | D32: 0 | E32: =Settings!$B$8 | F32: =D32/(1-E32) | G32: =D32*12 | I32: =IFERROR(VLOOKUP(H32,Roadmap!$A$7:$D$110,3,0),"not set, choose the event") | J32: 0 | K32: 12
A33: Performance Marketing Manager | D33: 0 | E33: =Settings!$B$8 | F33: =D33/(1-E33) | G33: =D33*12 | I33: =IFERROR(VLOOKUP(H33,Roadmap!$A$7:$D$110,3,0),"not set, choose the event") | J33: 0 | K33: 12
A34: Community Manager / SMM | D34: 0 | E34: =Settings!$B$8 | F34: =D34/(1-E34) | G34: =D34*12 | I34: =IFERROR(VLOOKUP(H34,Roadmap!$A$7:$D$110,3,0),"not set, choose the event") | J34: 0 | K34: 12
A35: PR / Comms Manager | D35: 0 | E35: =Settings!$B$8 | F35: =D35/(1-E35) | G35: =D35*12 | I35: =IFERROR(VLOOKUP(H35,Roadmap!$A$7:$D$110,3,0),"not set, choose the event") | J35: 0 | K35: 12
A36: Marketing Designer | D36: 0 | E36: =Settings!$B$8 | F36: =D36/(1-E36) | G36: =D36*12 | I36: =IFERROR(VLOOKUP(H36,Roadmap!$A$7:$D$110,3,0),"not set, choose the event") | J36: 0 | K36: 12
A37: Employee 3 | D37: 0 | E37: =Settings!$B$8 | F37: =D37/(1-E37) | G37: =D37*12 | I37: =IFERROR(VLOOKUP(H37,Roadmap!$A$7:$D$110,3,0),"not set, choose the event") | J37: 0 | K37: 12
A38: Employee 4 | D38: 0 | E38: =Settings!$B$8 | F38: =D38/(1-E38) | G38: =D38*12 | I38: =IFERROR(VLOOKUP(H38,Roadmap!$A$7:$D$110,3,0),"not set, choose the event") | J38: 0 | K38: 12
A40: Sales
A41: Head of Sales | D41: 5000 | E41: =Settings!$B$8 | F41: =D41/(1-E41) | G41: =D41*12 | H41: Incorporation | I41: =IFERROR(VLOOKUP(H41,Roadmap!$A$7:$D$110,3,0),"not set, choose the event") | J41: 0.02 | K41: 12
A42: BDM | D42: 5000 | E42: =Settings!$B$8 | F42: =D42/(1-E42) | G42: =D42*12 | H42: Incorporation | I42: =IFERROR(VLOOKUP(H42,Roadmap!$A$7:$D$110,3,0),"not set, choose the event") | J42: 0.02 | K42: 12
A43: Partnerships Manager | D43: 1000 | E43: =Settings!$B$8 | F43: =D43/(1-E43) | G43: =D43*12 | H43: Incorporation | I43: =IFERROR(VLOOKUP(H43,Roadmap!$A$7:$D$110,3,0),"not set, choose the event") | J43: 0.02 | K43: 12
A44: Inbound Sales Manager | D44: 1000 | E44: =Settings!$B$8 | F44: =D44/(1-E44) | G44: =D44*12 | H44: Incorporation | I44: =IFERROR(VLOOKUP(H44,Roadmap!$A$7:$D$110,3,0),"not set, choose the event") | J44: 0.02 | K44: 12
...

Sheet Projections
A1: Healthy4U Revenue Projections | K1: Updated: 2026-01-27
A3: CONSERVATIVE SCENARIO (3 doctors by Month 3)
A4: Month | B4: Doctors | C4: Doctor MRR | D4: Patients | E4: Patient MRR | F4: Rev Share | G4: Net Patient | H4: Total MRR | I4: Total COGS | J4: Profit | K4: Margin %
A5: 1 | B5: 1 | C5: $174 | D5: 15 | E5: $150 | F5: -$38 | G5: $112 | H5: $286 | I5: $80 | J5: $206 | K5: 72%
A6: 2 | B6: 2 | C6: $348 | D6: 30 | E6: $300 | F6: -$75 | G6: $225 | H6: $573 | I6: $159 | J6: $414 | K6: 72%
A7: 3 | B7: 3 | C7: $547 | D7: 45 | E7: $450 | F7: -$113 | G7: $337 | H7: $884 | I7: $239 | J7: $645 | K7: 73%
A9: Q1 Total Revenue | H9: $1,743
A10: Month 3 ARR | H10: $10,608
A12: TARGET SCENARIO (5 doctors by Month 3)
A13: Month | B13: Doctors | C13: Doctor MRR | D13: Patients | E13: Patient MRR | F13: Rev Share | G13: Net Patient | H13: Total MRR | I13: Total COGS | J13: Profit | K13: Margin %
A14: 1 | B14: 2 | C14: $348 | D14: 30 | E14: $300 | F14: -$75 | G14: $225 | H14: $573 | I14: $159 | J14: $414 | K14: 72%
A15: 2 | B15: 4 | C15: $721 | D15: 60 | E15: $599 | F15: -$150 | G15: $449 | H15: $1,170 | I15: $319 | J15: $852 | K15: 73%
A16: 3 | B16: 5 | C16: $920 | D16: 75 | E16: $749 | F16: -$188 | G16: $562 | H16: $1,482 | I16: $398 | J16: $1,084 | K16: 73%
A18: Q1 Total Revenue | H18: $3,225
A19: Month 3 ARR | H19: $17,781
A21: AGGRESSIVE SCENARIO (8 doctors by Month 6)
A22: Month | B22: Doctors | C22: Doctor MRR | D22: Patients | E22: Patient MRR | F22: Rev Share | G22: Net Patient | H22: Total MRR | I22: Total COGS | J22: Profit | K22: Margin %
A23: 6 | B23: 8 | C23: $1,880 | D23: 120 | E23: $1,199 | F23: -$300 | G23: $899 | H23: $2,779 | I23: $637 | J23: $2,142 | K23: 77%
A25: Month 6 ARR | H25: $33,345

Sheet Charts
B1: =Settings!$B$4
B2: KEY INDICATORS
B20: CAPITAL
C22: Months to reach break even | D22: =COUNTIF('P&L | Cash Flow | Balance'!28:28,"<=0")
C24: Capital required | D24: =iferror(-MIN('P&L | Cash Flow | Balance'!39:39),"-")
B26: REVENUE

Sheet For Pitchdeck
C2: =YEAR('Monthly forecast'!E2) | D2: =C2+1 | E2: =D2+1 | F2: =E2+1 | G2: =F2+1 | I2: * Для слайда питчдека "Финансовый прогноз" ("Financial Forecast") скопируйте таблицу и графики на этом листе, которые показывают динамику выручки и прибыли по годам.
B3: ='P&L | Cash Flow | Balance'!A6 | C3: =SUM(C4:C6) | D3: =SUM(D4:D6) | E3: =SUM(E4:E6) | F3: =SUM(F4:F6) | G3: =SUM(G4:G6)
B4: ='P&L | Cash Flow | Balance'!A7 | C4: =SUMIFS('P&L | Cash Flow | Balance'!D7:CW7,'P&L | Cash Flow | Balance'!D2:CW2,">="&DATE(C2,1,1),'P&L | Cash Flow | Balance'!D2:CW2,"<="&DATE(C2,12,31)) | D4: =SUMIFS('P&L | Cash Flow | Balance'!E7:CX7,'P&L | Cash Flow | Balance'!E2:CX2,">="&DATE(D2,1,1),'P&L | Cash Flow | Balance'!E2:CX2,"<="&DATE(D2,12,31)) | E4: =SUMIFS('P&L | Cash Flow | Balance'!F7:CY7,'P&L | Cash Flow | Balance'!F2:CY2,">="&DATE(E2,1,1),'P&L | Cash Flow | Balance'!F2:CY2,"<="&DATE(E2,12,31)) | F4: =SUMIFS('P&L | Cash Flow | Balance'!G7:CZ7,'P&L | Cash Flow | Balance'!G2:CZ2,">="&DATE(F2,1,1),'P&L | Cash Flow | Balance'!G2:CZ2,"<="&DATE(F2,12,31)) | G4: =SUMIFS('P&L | Cash Flow | Balance'!H7:DA7,'P&L | Cash Flow | Balance'!H2:DA2,">="&DATE(G2,1,1),'P&L | Cash Flow | Balance'!H2:DA2,"<="&DATE(G2,12,31))
B5: ='P&L | Cash Flow | Balance'!A8 | C5: =SUMIFS('P&L | Cash Flow | Balance'!D8:CW8,'P&L | Cash Flow | Balance'!D2:CW2,">="&DATE(C2,1,1),'P&L | Cash Flow | Balance'!D2:CW2,"<="&DATE(C2,12,31)) | D5: =SUMIFS('P&L | Cash Flow | Balance'!E8:CX8,'P&L | Cash Flow | Balance'!E2:CX2,">="&DATE(D2,1,1),'P&L | Cash Flow | Balance'!E2:CX2,"<="&DATE(D2,12,31)) | E5: =SUMIFS('P&L | Cash Flow | Balance'!F8:CY8,'P&L | Cash Flow | Balance'!F2:CY2,">="&DATE(E2,1,1),'P&L | Cash Flow | Balance'!F2:CY2,"<="&DATE(E2,12,31)) | F5: =SUMIFS('P&L | Cash Flow | Balance'!G8:CZ8,'P&L | Cash Flow | Balance'!G2:CZ2,">="&DATE(F2,1,1),'P&L | Cash Flow | Balance'!G2:CZ2,"<="&DATE(F2,12,31)) | G5: =SUMIFS('P&L | Cash Flow | Balance'!H8:DA8,'P&L | Cash Flow | Balance'!H2:DA2,">="&DATE(G2,1,1),'P&L | Cash Flow | Balance'!H2:DA2,"<="&DATE(G2,12,31))
B6: ='P&L | Cash Flow | Balance'!A9 | C6: =SUMIFS('P&L | Cash Flow | Balance'!D9:CW9,'P&L | Cash Flow | Balance'!D2:CW2,">="&DATE(C2,1,1),'P&L | Cash Flow | Balance'!D2:CW2,"<="&DATE(C2,12,31)) | D6: =SUMIFS('P&L | Cash Flow | Balance'!E9:CX9,'P&L | Cash Flow | Balance'!E2:CX2,">="&DATE(D2,1,1),'P&L | Cash Flow | Balance'!E2:CX2,"<="&DATE(D2,12,31)) | E6: =SUMIFS('P&L | Cash Flow | Balance'!F9:CY9,'P&L | Cash Flow | Balance'!F2:CY2,">="&DATE(E2,1,1),'P&L | Cash Flow | Balance'!F2:CY2,"<="&DATE(E2,12,31)) | F6: =SUMIFS('P&L | Cash Flow | Balance'!G9:CZ9,'P&L | Cash Flow | Balance'!G2:CZ2,">="&DATE(F2,1,1),'P&L | Cash Flow | Balance'!G2:CZ2,"<="&DATE(F2,12,31)) | G6: =SUMIFS('P&L | Cash Flow | Balance'!H9:DA9,'P&L | Cash Flow | Balance'!H2:DA2,">="&DATE(G2,1,1),'P&L | Cash Flow | Balance'!H2:DA2,"<="&DATE(G2,12,31))
B7: ='P&L | Cash Flow | Balance'!A17 | C7: =SUMIFS('P&L | Cash Flow | Balance'!D17:CW17,'P&L | Cash Flow | Balance'!D2:CW2,">="&DATE(C2,1,1),'P&L | Cash Flow | Balance'!D2:CW2,"<="&DATE(C2,12,31)) | D7: =SUMIFS('P&L | Cash Flow | Balance'!E17:CX17,'P&L | Cash Flow | Balance'!E2:CX2,">="&DATE(D2,1,1),'P&L | Cash Flow | Balance'!E2:CX2,"<="&DATE(D2,12,31)) | E7: =SUMIFS('P&L | Cash Flow | Balance'!F17:CY17,'P&L | Cash Flow | Balance'!F2:CY2,">="&DATE(E2,1,1),'P&L | Cash Flow | Balance'!F2:CY2,"<="&DATE(E2,12,31)) | F7: =SUMIFS('P&L | Cash Flow | Balance'!G17:CZ17,'P&L | Cash Flow | Balance'!G2:CZ2,">="&DATE(F2,1,1),'P&L | Cash Flow | Balance'!G2:CZ2,"<="&DATE(F2,12,31)) | G7: =SUMIFS('P&L | Cash Flow | Balance'!H17:DA17,'P&L | Cash Flow | Balance'!H2:DA2,">="&DATE(G2,1,1),'P&L | Cash Flow | Balance'!H2:DA2,"<="&DATE(G2,12,31))
B8: ='P&L | Cash Flow | Balance'!A28 | C8: =SUMIFS('P&L | Cash Flow | Balance'!D28:CW28,'P&L | Cash Flow | Balance'!D2:CW2,">="&DATE(C2,1,1),'P&L | Cash Flow | Balance'!D2:CW2,"<="&DATE(C2,12,31)) | D8: =SUMIFS('P&L | Cash Flow | Balance'!E28:CX28,'P&L | Cash Flow | Balance'!E2:CX2,">="&DATE(D2,1,1),'P&L | Cash Flow | Balance'!E2:CX2,"<="&DATE(D2,12,31)) | E8: =SUMIFS('P&L | Cash Flow | Balance'!F28:CY28,'P&L | Cash Flow | Balance'!F2:CY2,">="&DATE(E2,1,1),'P&L | Cash Flow | Balance'!F2:CY2,"<="&DATE(E2,12,31)) | F8: =SUMIFS('P&L | Cash Flow | Balance'!G28:CZ28,'P&L | Cash Flow | Balance'!G2:CZ2,">="&DATE(F2,1,1),'P&L | Cash Flow | Balance'!G2:CZ2,"<="&DATE(F2,12,31)) | G8: =SUMIFS('P&L | Cash Flow | Balance'!H28:DA28,'P&L | Cash Flow | Balance'!H2:DA2,">="&DATE(G2,1,1),'P&L | Cash Flow | Balance'!H2:DA2,"<="&DATE(G2,12,31))

Sheet Monthly forecast
A1: =Settings!B4
A2: Month | B2: Expense category | D2: =EDATE(E2,-1) | E2: =Projections!$B$4 | F2: =EDATE(E2,1) | G2: =EDATE(F2,1) | H2: =EDATE(G2,1) | I2: =EDATE(H2,1) | J2: =EDATE(I2,1) | K2: =EDATE(J2,1) | L2: =EDATE(K2,1) | M2: =EDATE(L2,1) | ... CX2: =EDATE(CW2,1)
A4: REVENUE
A6: KEY INDICATORS
A8: Traffic | Z8: =N8*(1+Projections!$B$14)
A9: Organic traffic | E9: =IF(E2=Projections!$D$13,Projections!$B$13,IF(E2>Projections!$D$13,MIN(D9*(1+Projections!$B$14),Projections!$B$15),0)) | F9: =IF(F2=Projections!$D$13,Projections!$B$13,IF(F2>Projections!$D$13,MIN(E9*(1+Projections!$B$14),Projections!$B$15),0)) | G9: =IF(G2=Projections!$D$13,Projections!$B$13,IF(G2>Projections!$D$13,MIN(F9*(1+Projections!$B$14),Projections!$B$15),0)) | H9: =IF(H2=Projections!$D$13,Projections!$B$13,IF(H2>Projections!$D$13,MIN(G9*(1+Projections!$B$14),Projections!$B$15),0)) | I9: =IF(I2=Projections!$D$13,Projections!$B$13,IF(I2>Projections!$D$13,MIN(H9*(1+Projections!$B$14),Projections!$B$15),0)) | J9: =IF(J2=Projections!$D$13,Projections!$B$13,IF(J2>Projections!$D$13,MIN(I9*(1+Projections!$B$14),Projections!$B$15),0)) | K9: =IF(K2=Projections!$D$13,Projections!$B$13,IF(K2>Projections!$D$13,MIN(J9*(1+Projections!$B$14),Projections!$B$15),0)) | L9: =IF(L2=Projections!$D$13,Projections!$B$13,IF(L2>Projections!$D$13,MIN(K9*(1+Projections!$B$14),Projections!$B$15),0)) | ... CX9: =IF(CX2=Projections!$D$13,Projections!$B$13,IF(CX2>Projections!$D$13,MIN(CW9*(1+Projections!$B$14),Projections!$B$15),0))
A10: CPC | E10: =IF(E2=Projections!$D$19,Projections!$B$21,IF(E2>Projections!$D$19,MAX(Projections!$B$23,D10*(1-Projections!$B$22)),0)) | F10: =IF(F2=Projections!$D$19,Projections!$B$21,IF(F2>Projections!$D$19,MAX(Projections!$B$23,E10*(1-Projections!$B$22)),0)) | G10: =IF(G2=Projections!$D$19,Projections!$B$21,IF(G2>Projections!$D$19,MAX(Projections!$B$23,F10*(1-Projections!$B$22)),0)) | H10: =IF(H2=Projections!$D$19,Projections!$B$21,IF(H2>Projections!$D$19,MAX(Projections!$B$23,G10*(1-Projections!$B$22)),0)) | I10: =IF(I2=Projections!$D$19,Projections!$B$21,IF(I2>Projections!$D$19,MAX(Projections!$B$23,H10*(1-Projections!$B$22)),0)) | J10: =IF(J2=Projections!$D$19,Projections!$B$21,IF(J2>Projections!$D$19,MAX(Projections!$B$23,I10*(1-Projections!$B$22)),0)) | K10: =IF(K2=Projections!$D$19,Projections!$B$21,IF(K2>Projections!$D$19,MAX(Projections!$B$23,J10*(1-Projections!$B$22)),0)) | L10: =IF(L2=Projections!$D$19,Projections!$B$21,IF(L2>Projections!$D$19,MAX(Projections!$B$23,K10*(1-Projections!$B$22)),0)) | ... CX10: =IF(CX2=Projections!$D$19,Projections!$B$21,IF(CX2>Projections!$D$19,MAX(Projections!$B$23,CW10*(1-Projections!$B$22)),0))
A11: Paid traffic | E11: =IFERROR(E65/E10,0) | F11: =IFERROR(F65/F10,0) | G11: =IFERROR(G65/G10,0) | H11: =IFERROR(H65/H10,0) | I11: =IFERROR(I65/I10,0) | J11: =IFERROR(J65/J10,0) | K11: =IFERROR(K65/K10,0) | L11: =IFERROR(L65/L10,0) | ... CX11: =IFERROR(CX65/CX10,0)
A12: Total traffic | E12: =SUM(E9:E11) | F12: =SUM(F9:F11) | G12: =SUM(G9:G11) | H12: =SUM(H9:H11) | I12: =SUM(I9:I11) | J12: =SUM(J9:J11) | K12: =SUM(K9:K11) | L12: =SUM(L9:L11) | ... CX12: =SUM(CX9:CX11)
A15: =Projections!A33
A17: New subscribers | E17: =if(E2>=Projections!$D$28,E12*Projections!$B$36,0) | F17: =if(F2>=Projections!$D$28,F12*Projections!$B$36,0) | G17: =if(G2>=Projections!$D$28,G12*Projections!$B$36,0) | H17: =if(H2>=Projections!$D$28,H12*Projections!$B$36,0) | I17: =if(I2>=Projections!$D$28,I12*Projections!$B$36,0) | J17: =if(J2>=Projections!$D$28,J12*Projections!$B$36,0) | K17: =if(K2>=Projections!$D$28,K12*Projections!$B$36,0) | L17: =if(L2>=Projections!$D$28,L12*Projections!$B$36,0) | ... CX17: =if(CX2>=Projections!$D$28,CX12*Projections!$B$36,0)
A18: Churn rate | E18: =IF(E2>=Projections!$D$28,Projections!$B$30,0) | F18: =IF(F2>=Projections!$D$28,Projections!$B$30,0) | G18: =IF(G2>=Projections!$D$28,Projections!$B$30,0) | H18: =IF(H2>=Projections!$D$28,Projections!$B$30,0) | I18: =IF(I2>=Projections!$D$28,Projections!$B$30,0) | J18: =IF(J2>=Projections!$D$28,Projections!$B$30,0) | K18: =IF(K2>=Projections!$D$28,Projections!$B$30,0) | L18: =IF(L2>=Projections!$D$28,Projections!$B$30,0) | ... CX18: =IF(CX2>=Projections!$D$28,Projections!$B$30,0)
A19: Lost subscribers | E19: =D20*E18 | F19: =E20*F18 | G19: =F20*G18 | H19: =G20*H18 | I19: =H20*I18 | J19: =I20*J18 | K19: =J20*K18 | L19: =K20*L18 | ... CX19: =CW20*CX18
A20: Subscribers - End of the period | E20: =D20+E17-E19 | F20: =E20+F17-F19 | G20: =F20+G17-G19 | H20: =G20+H17-H19 | I20: =H20+I17-I19 | J20: =I20+J17-J19 | K20: =J20+K17-K19 | L20: =K20+L17-L19 | ... CX20: =CW20+CX17-CX19
A22: Gross revenue Self-service | E22: =E20*Projections!$B$28 | F22: =F20*Projections!$B$28 | G22: =G20*Projections!$B$28 | H22: =H20*Projections!$B$28 | I22: =I20*Projections!$B$28 | J22: =J20*Projections!$B$28 | K22: =K20*Projections!$B$28 | L22: =L20*Projections!$B$28 | ... CX22: =CX20*Projections!$B$28
A24: =Projections!A39
A26: Leads | E26: =if(E2>=Projections!$C$42,E12*Projections!$B$45,0) | F26: =if(F2>=Projections!$C$42,F12*Projections!$B$45,0) | G26: =if(G2>=Projections!$C$42,G12*Projections!$B$45,0) | H26: =if(H2>=Projections!$C$42,H12*Projections!$B$45,0) | I26: =if(I2>=Projections!$C$42,I12*Projections!$B$45,0) | J26: =if(J2>=Projections!$C$42,J12*Projections!$B$45,0) | K26: =if(K2>=Projections!$C$42,K12*Projections!$B$45,0) | L26: =if(L2>=Projections!$C$42,L12*Projections!$B$45,0) | ... CX26: =if(CX2>=Projections!$C$42,CX12*Projections!$B$45,0)
A28: New subscribers | E28: =IFERROR(E26*Projections!$B$50,0) | F28: =IFERROR(F26*Projections!$B$50,0) | G28: =IFERROR(G26*Projections!$B$50,0) | H28: =IFERROR(H26*Projections!$B$50,0) | I28: =IFERROR(I26*Projections!$B$50,0) | J28: =IFERROR(J26*Projections!$B$50,0) | K28: =IFERROR(K26*Projections!$B$50,0) | L28: =IFERROR(L26*Projections!$B$50,0) | ... CX28: =IFERROR(CX26*Projections!$B$50,0)
A29: Churn rate | E29: =IF(E2>=Projections!$D$28,Projections!$B$30,0) | F29: =IF(F2>=Projections!$D$28,Projections!$B$30,0) | G29: =IF(G2>=Projections!$D$28,Projections!$B$30,0) | H29: =IF(H2>=Projections!$D$28,Projections!$B$30,0) | I29: =IF(I2>=Projections!$D$28,Projections!$B$30,0) | J29: =IF(J2>=Projections!$D$28,Projections!$B$30,0) | K29: =IF(K2>=Projections!$D$28,Projections!$B$30,0) | L29: =IF(L2>=Projections!$D$28,Projections!$B$30,0) | ... CX29: =IF(CX2>=Projections!$D$28,Projections!$B$30,0)
A30: Lost subscribers | E30: =D31*E29 | F30: =E31*F29 | G30: =F31*G29 | H30: =G31*H29 | I30: =H31*I29 | J30: =I31*J29 | K30: =J31*K29 | L30: =K31*L29 | ... CX30: =CW31*CX29
A31: Subscribers - End of the period | E31: =D31+E28-E30 | F31: =E31+F28-F30 | G31: =F31+G28-G30 | H31: =G31+H28-H30 | I31: =H31+I28-I30 | J31: =I31+J28-J30 | K31: =J31+K28-K30 | L31: =K31+L28-L30 | ... CX31: =CW31+CX28-CX30
A33: Gross revenue Inbound Sales | E33: =E31*Projections!$B$28 | F33: =F31*Projections!$B$28 | G33: =G31*Projections!$B$28 | H33: =H31*Projections!$B$28 | I33: =I31*Projections!$B$28 | J33: =J31*Projections!$B$28 | K33: =K31*Projections!$B$28 | L33: =L31*Projections!$B$28 | ... CX33: =CX31*Projections!$B$28
A35: =Projections!A53
A37: New subscribers | E37: =E87*Projections!$B$62 | F37: =F87*Projections!$B$62 | G37: =G87*Projections!$B$62 | H37: =H87*Projections!$B$62 | I37: =I87*Projections!$B$62 | J37: =J87*Projections!$B$62 | K37: =K87*Projections!$B$62 | L37: =L87*Projections!$B$62 | ... CX37: =CX87*Projections!$B$62
A38: Churn rate | E38: =IF(E2>=Projections!$D$28,Projections!$B$30,0) | F38: =IF(F2>=Projections!$D$28,Projections!$B$30,0) | G38: =IF(G2>=Projections!$D$28,Projections!$B$30,0) | H38: =IF(H2>=Projections!$D$28,Projections!$B$30,0) | I38: =IF(I2>=Projections!$D$28,Projections!$B$30,0) | J38: =IF(J2>=Projections!$D$28,Projections!$B$30,0) | K38: =IF(K2>=Projections!$D$28,Projections!$B$30,0) | L38: =IF(L2>=Projections!$D$28,Projections!$B$30,0) | ... CX38: =IF(CX2>=Projections!$D$28,Projections!$B$30,0)
A39: Lost subscribers | E39: =D40*E38 | F39: =E40*F38 | G39: =F40*G38 | H39: =G40*H38 | I39: =H40*I38 | J39: =I40*J38 | K39: =J40*K38 | L39: =K40*L38 | ... CX39: =CW40*CX38
A40: Subscribers - End of the period | E40: =D40+E37-E39 | F40: =E40+F37-F39 | G40: =F40+G37-G39 | H40: =G40+H37-H39 | I40: =H40+I37-I39 | J40: =I40+J37-J39 | K40: =J40+K37-K39 | L40: =K40+L37-L39 | ... CX40: =CW40+CX37-CX39
A42: Gross revenue Outbound Sales | E42: =E40*Projections!$B$28 | F42: =F40*Projections!$B$28 | G42: =G40*Projections!$B$28 | H42: =H40*Projections!$B$28 | I42: =I40*Projections!$B$28 | J42: =J40*Projections!$B$28 | K42: =K40*Projections!$B$28 | L42: =L40*Projections!$B$28 | ... CX42: =CX40*Projections!$B$28
A44: Total subscribers - End of the period | E44: =E40+E31+E20 | F44: =F40+F31+F20 | G44: =G40+G31+G20 | H44: =H40+H31+H20 | I44: =I40+I31+I20 | J44: =J40+J31+J20 | K44: =K40+K31+K20 | L44: =L40+L31+L20 | ... CX44: =CX40+CX31+CX20
A45: Total gross revenue | E45: =E42+E33+E22 | F45: =F42+F33+F22 | G45: =G42+G33+G22 | H45: =H42+H33+H22 | I45: =I42+I33+I22 | J45: =J42+J33+J22 | K45: =K42+K33+K22 | L45: =L42+L33+L22 | ... CX45: =CX42+CX33+CX22
A47: COGS | E47: =SUM(E49:E50) | F47: =SUM(F49:F50) | G47: =SUM(G49:G50) | H47: =SUM(H49:H50) | I47: =SUM(I49:I50) | J47: =SUM(J49:J50) | K47: =SUM(K49:K50) | L47: =SUM(L49:L50) | ... CX47: =SUM(CX49:CX50)
A49: Hosting | E49: =E44*Projections!$B$68 | F49: =F44*Projections!$B$68 | G49: =G44*Projections!$B$68 | H49: =H44*Projections!$B$68 | I49: =I44*Projections!$B$68 | J49: =J44*Projections!$B$68 | K49: =K44*Projections!$B$68 | L49: =L44*Projections!$B$68 | ... CX49: =CX44*Projections!$B$68
A50: Payments processing | E50: =E45*Projections!$B$67 | F50: =F45*Projections!$B$67 | G50: =G45*Projections!$B$67 | H50: =H45*Projections!$B$67 | I50: =I45*Projections!$B$67 | J50: =J45*Projections!$B$67 | K50: =K45*Projections!$B$67 | L50: =L45*Projections!$B$67 | ... CX50: =CX45*Projections!$B$67
A53: SG&A | E53: =E55+E79+E91+E139+E151 | F53: =F55+F79+F91+F139+F151 | G53: =G55+G79+G91+G139+G151 | H53: =H55+H79+H91+H139+H151 | I53: =I55+I79+I91+I139+I151 | J53: =J55+J79+J91+J139+J151 | K53: =K55+K79+K91+K139+K151 | L53: =L55+L79+L91+L139+L151 | ... CX53: =CX55+CX79+CX91+CX139+CX151
A55: MARKETING | E55: =E57+E65+E68 | F55: =F57+F65+F68 | G55: =G57+G65+G68 | H55: =H57+H65+H68 | I55: =I57+I65+I68 | J55: =J57+J65+J68 | K55: =K57+K65+K68 | L55: =L57+L65+L68 | ... CX55: =CX57+CX65+CX68
A57: =Projections!A75 | B57: Marketing | E57: =SUM(E58:E60) | F57: =SUM(F58:F60) | G57: =SUM(G58:G60) | H57: =SUM(H58:H60) | I57: =SUM(I58:I60) | J57: =SUM(J58:J60) | K57: =SUM(K58:K60) | L57: =SUM(L58:L60) | ... CX57: =SUM(CX58:CX60)
A58: =Projections!A76 | E58: =IF(E$2<Projections!$D76,0,IF(and(E$2>=Projections!$D76,E$2<Projections!$F76),Projections!$B76,if(and(E$2>=Projections!$F76,E$2<Projections!$I76),Projections!$B76+Projections!$G76,if(and(E$2>=Projections!$I76,E$2<Projections!$L76),Projections!$B76+Projections!$G76+Projections!$J76,IF(E$2>=Projections!$L76,Projections!$B76+Projections!$G76+Projections!$J76+Projections!$M76,""))))) | F58: =IF(F$2<Projections!$D76,0,IF(and(F$2>=Projections!$D76,F$2<Projections!$F76),Projections!$B76,if(and(F$2>=Projections!$F76,F$2<Projections!$I76),Projections!$B76+Projections!$G76,if(and(F$2>=Projections!$I76,F$2<Projections!$L76),Projections!$B76+Projections!$G76+Projections!$J76,IF(F$2>=Projections!$L76,Projections!$B76+Projections!$G76+Projections!$J76+Projections!$M76,""))))) | G58: =IF(G$2<Projections!$D76,0,IF(and(G$2>=Projections!$D76,G$2<Projections!$F76),Projections!$B76,if(and(G$2>=Projections!$F76,G$2<Projections!$I76),Projections!$B76+Projections!$G76,if(and(G$2>=Projections!$I76,G$2<Projections!$L76),Projections!$B76+Projections!$G76+Projections!$J76,IF(G$2>=Projections!$L76,Projections!$B76+Projections!$G76+Projections!$J76+Projections!$M76,""))))) | H58: =IF(H$2<Projections!$D76,0,IF(and(H$2>=Projections!$D76,H$2<Projections!$F76),Projections!$B76,if(and(H$2>=Projections!$F76,H$2<Projections!$I76),Projections!$B76+Projections!$G76,if(and(H$2>=Projections!$I76,H$2<Projections!$L76),Projections!$B76+Projections!$G76+Projections!$J76,IF(H$2>=Projections!$L76,Projections!$B76+Projections!$G76+Projections!$J76+Projections!$M76,""))))) | I58: =IF(I$2<Projections!$D76,0,IF(and(I$2>=Projections!$D76,I$2<Projections!$F76),Projections!$B76,if(and(I$2>=Projections!$F76,I$2<Projections!$I76),Projections!$B76+Projections!$G76,if(and(I$2>=Projections!$I76,I$2<Projections!$L76),Projections!$B76+Projections!$G76+Projections!$J76,IF(I$2>=Projections!$L76,Projections!$B76+Projections!$G76+Projections!$J76+Projections!$M76,""))))) | J58: =IF(J$2<Projections!$D76,0,IF(and(J$2>=Projections!$D76,J$2<Projections!$F76),Projections!$B76,if(and(J$2>=Projections!$F76,J$2<Projections!$I76),Projections!$B76+Projections!$G76,if(and(J$2>=Projections!$I76,J$2<Projections!$L76),Projections!$B76+Projections!$G76+Projections!$J76,IF(J$2>=Projections!$L76,Projections!$B76+Projections!$G76+Projections!$J76+Projections!$M76,""))))) | K58: =IF(K$2<Projections!$D76,0,IF(and(K$2>=Projections!$D76,K$2<Projections!$F76),Projections!$B76,if(and(K$2>=Projections!$F76,K$2<Projections!$I76),Projections!$B76+Projections!$G76,if(and(K$2>=Projections!$I76,K$2<Projections!$L76),Projections!$B76+Projections!$G76+Projections!$J76,IF(K$2>=Projections!$L76,Projections!$B76+Projections!$G76+Projections!$J76+Projections!$M76,""))))) | L58: =IF(L$2<Projections!$D76,0,IF(and(L$2>=Projections!$D76,L$2<Projections!$F76),Projections!$B76,if(and(L$2>=Projections!$F76,L$2<Projections!$I76),Projections!$B76+Projections!$G76,if(and(L$2>=Projections!$I76,L$2<Projections!$L76),Projections!$B76+Projections!$G76+Projections!$J76,IF(L$2>=Projections!$L76,Projections!$B76+Projections!$G76+Projections!$J76+Projections!$M76,""))))) | ... CX58: =IF(CX$2<Projections!$D76,0,IF(and(CX$2>=Projections!$D76,CX$2<Projections!$F76),Projections!$B76,if(and(CX$2>=Projections!$F76,CX$2<Projections!$I76),Projections!$B76+Projections!$G76,if(and(CX$2>=Projections!$I76,CX$2<Projections!$L76),Projections!$B76+Projections!$G76+Projections!$J76,IF(CX$2>=Projections!$L76,Projections!$B76+Projections!$G76+Projections!$J76+Projections!$M76,"")))))
A59: =Projections!A77 | E59: =IF(E$2<Projections!$D77,0,IF(and(E$2>=Projections!$D77,E$2<Projections!$F77),Projections!$B77,if(and(E$2>=Projections!$F77,E$2<Projections!$I77),Projections!$B77+Projections!$G77,if(and(E$2>=Projections!$I77,E$2<Projections!$L77),Projections!$B77+Projections!$G77+Projections!$J77,IF(E$2>=Projections!$L77,Projections!$B77+Projections!$G77+Projections!$J77+Projections!$M77,""))))) | F59: =IF(F$2<Projections!$D77,0,IF(and(F$2>=Projections!$D77,F$2<Projections!$F77),Projections!$B77,if(and(F$2>=Projections!$F77,F$2<Projections!$I77),Projections!$B77+Projections!$G77,if(and(F$2>=Projections!$I77,F$2<Projections!$L77),Projections!$B77+Projections!$G77+Projections!$J77,IF(F$2>=Projections!$L77,Projections!$B77+Projections!$G77+Projections!$J77+Projections!$M77,""))))) | G59: =IF(G$2<Projections!$D77,0,IF(and(G$2>=Projections!$D77,G$2<Projections!$F77),Projections!$B77,if(and(G$2>=Projections!$F77,G$2<Projections!$I77),Projections!$B77+Projections!$G77,if(and(G$2>=Projections!$I77,G$2<Projections!$L77),Projections!$B77+Projections!$G77+Projections!$J77,IF(G$2>=Projections!$L77,Projections!$B77+Projections!$G77+Projections!$J77+Projections!$M77,""))))) | H59: =IF(H$2<Projections!$D77,0,IF(and(H$2>=Projections!$D77,H$2<Projections!$F77),Projections!$B77,if(and(H$2>=Projections!$F77,H$2<Projections!$I77),Projections!$B77+Projections!$G77,if(and(H$2>=Projections!$I77,H$2<Projections!$L77),Projections!$B77+Projections!$G77+Projections!$J77,IF(H$2>=Projections!$L77,Projections!$B77+Projections!$G77+Projections!$J77+Projections!$M77,""))))) | I59: =IF(I$2<Projections!$D77,0,IF(and(I$2>=Projections!$D77,I$2<Projections!$F77),Projections!$B77,if(and(I$2>=Projections!$F77,I$2<Projections!$I77),Projections!$B77+Projections!$G77,if(and(I$2>=Projections!$I77,I$2<Projections!$L77),Projections!$B77+Projections!$G77+Projections!$J77,IF(I$2>=Projections!$L77,Projections!$B77+Projections!$G77+Projections!$J77+Projections!$M77,""))))) | J59: =IF(J$2<Projections!$D77,0,IF(and(J$2>=Projections!$D77,J$2<Projections!$F77),Projections!$B77,if(and(J$2>=Projections!$F77,J$2<Projections!$I77),Projections!$B77+Projections!$G77,if(and(J$2>=Projections!$I77,J$2<Projections!$L77),Projections!$B77+Projections!$G77+Projections!$J77,IF(J$2>=Projections!$L77,Projections!$B77+Projections!$G77+Projections!$J77+Projections!$M77,""))))) | K59: =IF(K$2<Projections!$D77,0,IF(and(K$2>=Projections!$D77,K$2<Projections!$F77),Projections!$B77,if(and(K$2>=Projections!$F77,K$2<Projections!$I77),Projections!$B77+Projections!$G77,if(and(K$2>=Projections!$I77,K$2<Projections!$L77),Projections!$B77+Projections!$G77+Projections!$J77,IF(K$2>=Projections!$L77,Projections!$B77+Projections!$G77+Projections!$J77+Projections!$M77,""))))) | L59: =IF(L$2<Projections!$D77,0,IF(and(L$2>=Projections!$D77,L$2<Projections!$F77),Projections!$B77,if(and(L$2>=Projections!$F77,L$2<Projections!$I77),Projections!$B77+Projections!$G77,if(and(L$2>=Projections!$I77,L$2<Projections!$L77),Projections!$B77+Projections!$G77+Projections!$J77,IF(L$2>=Projections!$L77,Projections!$B77+Projections!$G77+Projections!$J77+Projections!$M77,""))))) | ... CX59: =IF(CX$2<Projections!$D77,0,IF(and(CX$2>=Projections!$D77,CX$2<Projections!$F77),Projections!$B77,if(and(CX$2>=Projections!$F77,CX$2<Projections!$I77),Projections!$B77+Projections!$G77,if(and(CX$2>=Projections!$I77,CX$2<Projections!$L77),Projections!$B77+Projections!$G77+Projections!$J77,IF(CX$2>=Projections!$L77,Projections!$B77+Projections!$G77+Projections!$J77+Projections!$M77,"")))))
A60: =Projections!A78 | E60: =IF(E$2<Projections!$D78,0,IF(and(E$2>=Projections!$D78,E$2<Projections!$F78),Projections!$B78,if(and(E$2>=Projections!$F78,E$2<Projections!$I78),Projections!$B78+Projections!$G78,if(and(E$2>=Projections!$I78,E$2<Projections!$L78),Projections!$B78+Projections!$G78+Projections!$J78,IF(E$2>=Projections!$L78,Projections!$B78+Projections!$G78+Projections!$J78+Projections!$M78,""))))) | F60: =IF(F$2<Projections!$D78,0,IF(and(F$2>=Projections!$D78,F$2<Projections!$F78),Projections!$B78,if(and(F$2>=Projections!$F78,F$2<Projections!$I78),Projections!$B78+Projections!$G78,if(and(F$2>=Projections!$I78,F$2<Projections!$L78),Projections!$B78+Projections!$G78+Projections!$J78,IF(F$2>=Projections!$L78,Projections!$B78+Projections!$G78+Projections!$J78+Projections!$M78,""))))) | G60: =IF(G$2<Projections!$D78,0,IF(and(G$2>=Projections!$D78,G$2<Projections!$F78),Projections!$B78,if(and(G$2>=Projections!$F78,G$2<Projections!$I78),Projections!$B78+Projections!$G78,if(and(G$2>=Projections!$I78,G$2<Projections!$L78),Projections!$B78+Projections!$G78+Projections!$J78,IF(G$2>=Projections!$L78,Projections!$B78+Projections!$G78+Projections!$J78+Projections!$M78,""))))) | H60: =IF(H$2<Projections!$D78,0,IF(and(H$2>=Projections!$D78,H$2<Projections!$F78),Projections!$B78,if(and(H$2>=Projections!$F78,H$2<Projections!$I78),Projections!$B78+Projections!$G78,if(and(H$2>=Projections!$I78,H$2<Projections!$L78),Projections!$B78+Projections!$G78+Projections!$J78,IF(H$2>=Projections!$L78,Projections!$B78+Projections!$G78+Projections!$J78+Projections!$M78,""))))) | I60: =IF(I$2<Projections!$D78,0,IF(and(I$2>=Projections!$D78,I$2<Projections!$F78),Projections!$B78,if(and(I$2>=Projections!$F78,I$2<Projections!$I78),Projections!$B78+Projections!$G78,if(and(I$2>=Projections!$I78,I$2<Projections!$L78),Projections!$B78+Projections!$G78+Projections!$J78,IF(I$2>=Projections!$L78,Projections!$B78+Projections!$G78+Projections!$J78+Projections!$M78,""))))) | J60: =IF(J$2<Projections!$D78,0,IF(and(J$2>=Projections!$D78,J$2<Projections!$F78),Projections!$B78,if(and(J$2>=Projections!$F78,J$2<Projections!$I78),Projections!$B78+Projections!$G78,if(and(J$2>=Projections!$I78,J$2<Projections!$L78),Projections!$B78+Projections!$G78+Projections!$J78,IF(J$2>=Projections!$L78,Projections!$B78+Projections!$G78+Projections!$J78+Projections!$M78,""))))) | K60: =IF(K$2<Projections!$D78,0,IF(and(K$2>=Projections!$D78,K$2<Projections!$F78),Projections!$B78,if(and(K$2>=Projections!$F78,K$2<Projections!$I78),Projections!$B78+Projections!$G78,if(and(K$2>=Projections!$I78,K$2<Projections!$L78),Projections!$B78+Projections!$G78+Projections!$J78,IF(K$2>=Projections!$L78,Projections!$B78+Projections!$G78+Projections!$J78+Projections!$M78,""))))) | L60: =IF(L$2<Projections!$D78,0,IF(and(L$2>=Projections!$D78,L$2<Projections!$F78),Projections!$B78,if(and(L$2>=Projections!$F78,L$2<Projections!$I78),Projections!$B78+Projections!$G78,if(and(L$2>=Projections!$I78,L$2<Projections!$L78),Projections!$B78+Projections!$G78+Projections!$J78,IF(L$2>=Projections!$L78,Projections!$B78+Projections!$G78+Projections!$J78+Projections!$M78,""))))) | ... CX60: =IF(CX$2<Projections!$D78,0,IF(and(CX$2>=Projections!$D78,CX$2<Projections!$F78),Projections!$B78,if(and(CX$2>=Projections!$F78,CX$2<Projections!$I78),Projections!$B78+Projections!$G78,if(and(CX$2>=Projections!$I78,CX$2<Projections!$L78),Projections!$B78+Projections!$G78+Projections!$J78,IF(CX$2>=Projections!$L78,Projections!$B78+Projections!$G78+Projections!$J78+Projections!$M78,"")))))
A64: Direct response campaigns
...

Sheet Unit economics
A1: =Settings!B4
A2: Month | C2: ='Monthly forecast'!D2 | D2: ='Monthly forecast'!E2 | E2: =EDATE(D2,1) | F2: =EDATE(E2,1) | G2: =EDATE(F2,1) | H2: =EDATE(G2,1) | I2: =EDATE(H2,1) | J2: =EDATE(I2,1) | K2: =EDATE(J2,1) | L2: =EDATE(K2,1) | ... CW2: =EDATE(CV2,1)
A4: ='Monthly forecast'!A15
A6: Subscription price per month | C6: =IF(C2>=Projections!$D$28,Projections!$B$28,0) | D6: =IF(D2>=Projections!$D$28,Projections!$B$28,0) | E6: =IF(E2>=Projections!$D$28,Projections!$B$28,0) | F6: =IF(F2>=Projections!$D$28,Projections!$B$28,0) | G6: =IF(G2>=Projections!$D$28,Projections!$B$28,0) | H6: =IF(H2>=Projections!$D$28,Projections!$B$28,0) | I6: =IF(I2>=Projections!$D$28,Projections!$B$28,0) | J6: =IF(J2>=Projections!$D$28,Projections!$B$28,0) | ... CW6: =IF(CW2>=Projections!$D$28,Projections!$B$28,0)
A7: ARPPU | C7: =C6 | D7: =D6 | E7: =E6 | F7: =F6 | G7: =G6 | H7: =H6 | I7: =I6 | J7: =J6 | ... CW7: =CW6
A9: Churn | C9: ='Monthly forecast'!D18 | D9: ='Monthly forecast'!E18 | E9: ='Monthly forecast'!F18 | F9: ='Monthly forecast'!G18 | G9: ='Monthly forecast'!H18 | H9: ='Monthly forecast'!I18 | I9: ='Monthly forecast'!J18 | J9: ='Monthly forecast'!K18 | ... CW9: ='Monthly forecast'!CX18
A10: LT (Ilifetime) | C10: =IFERROR(1/C9,0) | D10: =IFERROR(1/D9,0) | E10: =IFERROR(1/E9,0) | F10: =IFERROR(1/F9,0) | G10: =IFERROR(1/G9,0) | H10: =IFERROR(1/H9,0) | I10: =IFERROR(1/I9,0) | J10: =IFERROR(1/J9,0) | ... CW10: =IFERROR(1/CW9,0)
A12: LTV | C12: =C7*C10 | D12: =D7*D10 | E12: =E7*E10 | F12: =F7*F10 | G12: =G7*G10 | H12: =H7*H10 | I12: =I7*I10 | J12: =J7*J10 | ... CW12: =CW7*CW10
A13: LTV 3 month | C13: =C7*3 | D13: =D7*3 | E13: =E7*3 | F13: =F7*3 | G13: =G7*3 | H13: =H7*3 | I13: =I7*3 | J13: =J7*3 | ... CW13: =CW7*3
A14: LTV 6 month | C14: =C7*6 | D14: =D7*6 | E14: =E7*6 | F14: =F7*6 | G14: =G7*6 | H14: =H7*6 | I14: =I7*6 | J14: =J7*6 | ... CW14: =CW7*6
A15: LTV 12 month | C15: =C7*12 | D15: =D7*12 | E15: =E7*12 | F15: =F7*12 | G15: =G7*12 | H15: =H7*12 | I15: =I7*12 | J15: =J7*12 | ... CW15: =CW7*12
A17: pCAC (CAC paid channels) | D17: ='Monthly forecast'!E10/Projections!$B$36 | E17: ='Monthly forecast'!F10/Projections!$B$36 | F17: ='Monthly forecast'!G10/Projections!$B$36 | G17: ='Monthly forecast'!H10/Projections!$B$36 | H17: ='Monthly forecast'!I10/Projections!$B$36 | I17: ='Monthly forecast'!J10/Projections!$B$36 | J17: ='Monthly forecast'!K10/Projections!$B$36 | K17: ='Monthly forecast'!L10/Projections!$B$36 | ... CW17: ='Monthly forecast'!CX10/Projections!$B$36
A18: LTV/CAC | D18: =D12/D$17 | E18: =E12/E$17 | F18: =F12/F$17 | G18: =G12/G$17 | H18: =H12/H$17 | I18: =I12/I$17 | J18: =J12/J$17 | K18: =K12/K$17 | ... CW18: =CW12/CW$17
A19: LTV 3 month/CAC | D19: =D13/D$17 | E19: =E13/E$17 | F19: =F13/F$17 | G19: =G13/G$17 | H19: =H13/H$17 | I19: =I13/I$17 | J19: =J13/J$17 | K19: =K13/K$17 | ... CW19: =CW13/CW$17
A20: LTV 6 month/CAC | D20: =D14/D$17 | E20: =E14/E$17 | F20: =F14/F$17 | G20: =G14/G$17 | H20: =H14/H$17 | I20: =I14/I$17 | J20: =J14/J$17 | K20: =K14/K$17 | ... CW20: =CW14/CW$17
A21: LTV 12 month/CAC | D21: =D15/D$17 | E21: =E15/E$17 | F21: =F15/F$17 | G21: =G15/G$17 | H21: =H15/H$17 | I21: =I15/I$17 | J21: =J15/J$17 | K21: =K15/K$17 | ... CW21: =CW15/CW$17
A24: ='Monthly forecast'!A24
A26: Subscription price per month | C26: =IF(C2>=Projections!$D$28,Projections!$B$28,0) | D26: =IF(D2>=Projections!$D$28,Projections!$B$28,0) | E26: =IF(E2>=Projections!$D$28,Projections!$B$28,0) | F26: =IF(F2>=Projections!$D$28,Projections!$B$28,0) | G26: =IF(G2>=Projections!$D$28,Projections!$B$28,0) | H26: =IF(H2>=Projections!$D$28,Projections!$B$28,0) | I26: =IF(I2>=Projections!$D$28,Projections!$B$28,0) | J26: =IF(J2>=Projections!$D$28,Projections!$B$28,0) | ... CW26: =IF(CW2>=Projections!$D$28,Projections!$B$28,0)
A27: ARPPU | C27: =C26 | D27: =D26 | E27: =E26 | F27: =F26 | G27: =G26 | H27: =H26 | I27: =I26 | J27: =J26 | ... CW27: =CW26
A29: Churn | C29: ='Monthly forecast'!D38 | D29: ='Monthly forecast'!E29 | E29: ='Monthly forecast'!F29 | F29: ='Monthly forecast'!G29 | G29: ='Monthly forecast'!H29 | H29: ='Monthly forecast'!I29 | I29: ='Monthly forecast'!J29 | J29: ='Monthly forecast'!K29 | K29: ='Monthly forecast'!L29 | ... CW29: ='Monthly forecast'!CX29
A30: LT (Ilifetime) | C30: =IFERROR(1/C29,0) | D30: =IFERROR(1/D29,0) | E30: =IFERROR(1/E29,0) | F30: =IFERROR(1/F29,0) | G30: =IFERROR(1/G29,0) | H30: =IFERROR(1/H29,0) | I30: =IFERROR(1/I29,0) | J30: =IFERROR(1/J29,0) | ... CW30: =IFERROR(1/CW29,0)
A32: LTV | C32: =C27*C30 | D32: =D27*D30 | E32: =E27*E30 | F32: =F27*F30 | G32: =G27*G30 | H32: =H27*H30 | I32: =I27*I30 | J32: =J27*J30 | ... CW32: =CW27*CW30
A33: LTV 3 month | C33: =C27*3 | D33: =D27*3 | E33: =E27*3 | F33: =F27*3 | G33: =G27*3 | H33: =H27*3 | I33: =I27*3 | J33: =J27*3 | ... CW33: =CW27*3
A34: LTV 6 month | C34: =C27*6 | D34: =D27*6 | E34: =E27*6 | F34: =F27*6 | G34: =G27*6 | H34: =H27*6 | I34: =I27*6 | J34: =J27*6 | ... CW34: =CW27*6
A35: LTV 12 month | C35: =C27*12 | D35: =D27*12 | E35: =E27*12 | F35: =F27*12 | G35: =G27*12 | H35: =H27*12 | I35: =I27*12 | J35: =J27*12 | ... CW35: =CW27*12
A37: Marketing Costs | D37: ='Monthly forecast'!E10/Projections!$B$45/Projections!$B$50 | E37: ='Monthly forecast'!F10/Projections!$B$45/Projections!$B$50 | F37: ='Monthly forecast'!G10/Projections!$B$45/Projections!$B$50 | G37: ='Monthly forecast'!H10/Projections!$B$45/Projections!$B$50 | H37: ='Monthly forecast'!I10/Projections!$B$45/Projections!$B$50 | I37: ='Monthly forecast'!J10/Projections!$B$45/Projections!$B$50 | J37: ='Monthly forecast'!K10/Projections!$B$45/Projections!$B$50 | K37: ='Monthly forecast'!L10/Projections!$B$45/Projections!$B$50 | ... CW37: ='Monthly forecast'!CX10/Projections!$B$45/Projections!$B$50
A38: Cost of Inbound Sales Managers team | D38: ='Monthly forecast'!E83/(Projections!$B$49*Projections!$B$50) | E38: ='Monthly forecast'!F83/(Projections!$B$49*Projections!$B$50) | F38: ='Monthly forecast'!G83/(Projections!$B$49*Projections!$B$50) | G38: ='Monthly forecast'!H83/(Projections!$B$49*Projections!$B$50) | H38: ='Monthly forecast'!I83/(Projections!$B$49*Projections!$B$50) | I38: ='Monthly forecast'!J83/(Projections!$B$49*Projections!$B$50) | J38: ='Monthly forecast'!K83/(Projections!$B$49*Projections!$B$50) | K38: ='Monthly forecast'!L83/(Projections!$B$49*Projections!$B$50) | ... CW38: ='Monthly forecast'!CX83/(Projections!$B$49*Projections!$B$50)
A39: CAC | D39: =D37+D38 | E39: =E37+E38 | F39: =F37+F38 | G39: =G37+G38 | H39: =H37+H38 | I39: =I37+I38 | J39: =J37+J38 | K39: =K37+K38 | ... CW39: =CW37+CW38
A41: LTV/CAC | D41: =D32/D39 | E41: =E32/E39 | F41: =F32/F39 | G41: =G32/G39 | H41: =H32/H39 | I41: =I32/I39 | J41: =J32/J39 | K41: =K32/K39 | ... CV41: =CV32/CV39
A42: LTV 3 month/CAC | D42: =D33/D$39 | E42: =E33/E$39 | F42: =F33/F$39 | G42: =G33/G$39 | H42: =H33/H$39 | I42: =I33/I$39 | J42: =J33/J$39 | K42: =K33/K$39 | ... CW42: =CW33/CW$39
A43: LTV 6 month/CAC | D43: =D34/D$39 | E43: =E34/E$39 | F43: =F34/F$39 | G43: =G34/G$39 | H43: =H34/H$39 | I43: =I34/I$39 | J43: =J34/J$39 | K43: =K34/K$39 | ... CW43: =CW34/CW$39
A44: LTV 12 month/CAC | D44: =D35/D$39 | E44: =E35/E$39 | F44: =F35/F$39 | G44: =G35/G$39 | H44: =H35/H$39 | I44: =I35/I$39 | J44: =J35/J$39 | K44: =K35/K$39 | ... CW44: =CW35/CW$39
A46: ='Monthly forecast'!A35
