Workbook

Sheet Description
B1: Сайт: | C1: https://anastasianikolaeva.com/ | D1: Телеграм: | E1: https://t.me/anikolayeva
C2: Материалы этого файла могут быть использованы только лицом, купившим данный материал на сайте https://anastasianikolaeva.com/, в целях индивидуального обучения и развития своих бизнес-проектов. Массовое распространение данного материала, продажа и передача 3м лицам являются нарушением авторского права. Если вы хотите порекомендовать материалы своим коллегам, партнерам и друзьям, поделитесь ссылкой на сайт: https://anastasianikolaeva.com/
B3: Если вы хотите получить консультацию или заказать разработку финансовой модели для вашей компании, запишитесь на пробную бесплатную консультацию здесь: https://anastasianikolaeva.com/#expressform
B4: Финансовая модель
B6: Данный шаблон разработан для прогнозирования доходов и расходов компании, продающей цифровые решения по модели "Подписка". Мы рассматриваем 3 потока дохода, которые основаны на способе привлечения клиентов: наиболее популярных способа монетизации для такого продукта: "Самостоятельное приобретение подписки", "Входящие продажи" и "Исходящие продажи". Эта финансовая модель позволяет спрогнозировать точку безубыточности и оценить сумму необходимых инвестиций. Модель автоматически рассчитывает прогноз для вашего бизнеса во вкладках "Monthly forecast", "P&L | Cash Flow | Balance", "Unit Economics" и визуализирует их в "Charts" "For Pitchdeck" на основании данных, введенных на вкладках "Settings", "Roadmap", "Payroll", "Projections".
B9: Инструкции
B11: 1000 | D11: Синим шрифтом выделены поля, куда вносятся данные.
B12: 2000 | D12: Черным шрифтом выделены поля, в которых вычисления производятся по формулам.
B13: Incorporation | D13: В выпадающих списках заданы списки параметров, выбор которых влияет на расчеты в модели.
B14: Вкладка "Setting" | D14: В этой вкладке задаются общие параметры бизнеса. На основании указанных здесь налоговых ставок рассчитывается налог на прибыль во вкладке "P&L and Cash Flow" и налог на заработную плату во вкладке "Payroll".
B15: Вкладка "Roadmap" | D15: В этой вкладке перечисляются события дорожной карты бизнеса, которые будут влиять на динамику доходов и расходов компании. Здесь нужно перечислить такие события и указать их плановые даты. Даты можно задать, указав, через сколько месяцев после привлечения инвестиций произойдет событие. Перечисленные в этой вкладке события попадают в выпадающие списки на вкладках "Payroll" и "Projections". Благодаря этому вы можете привязывать появление новых затрат или доходов и найм определенных сотрудников к событиям в вашей дорожной карте. В зависимости от выбранного события во вкладках "Payroll" и "Projections" автоматически проставляются даты, начиная с которых возникают отдельные доходы и расходы, а во вкладке "Monthly Forecast" начинают учитываться эти данные с нужного месяца.
B16: Вкладка "Payroll" | D16: В этой вкладке вносятся все позиции наемных сотрудников, которые неоходимы вашему бизнесу, их зарплаты, события, при которых они нанимаются, и динамика увеличения зарплат. Здесь нужно внести названия должностей, размер зарплат, выбрать событие из дорожной карты, при котором происходит найм, указать планируемый процент ежегодного увеличения зарплат. Общие затраты на сотрудника с учетом налогов рассчитаются на основании ставки, указанной в "Settings", даты найма проставятся из "Roadmap" на основании выбранного события.
B17: Вкладка "Projections" | D17: В этой вкладке вносятся вводные данные для формирования всех потоков доходов и расходов. Здесь перечисляются все статьи доходов и расходов, задаются их значения, стартовые даты, периодичность и методы расчета динамики. При этом начало возникновения различных статей доходов и расходов связано с событиями дорожной карты, а генерация доходов зависит от прямых расходов, приводящих к продажам. На основании внесенных здесь значений формируется прогноз во вкладке "Monthly forecast".
B18: Вкладка "Monthly Forecast" | D18: В этой вкладке формируется подробный финансовый прогноз бизнеса по месяцам. Все расчеты производятся на основании данных, внесенных во вкладки "Settings", "Roadmap", "Payroll", "Projections" по заданным формулам. В этой вкладке ничего вносить не нужно.
B19: Вкладка "Unit Economics" | D19: В этой вкладке формируется расчет юнит экономики отдельно для каждого варианта монетизации. Расчитывается LTV продукта, CAC (стоимость привлечения клиента), отношение LTV к CAC.
B20: Вкладка "P&L and Cash Flow" | D20: В этой вкладке формируются финансовые отчеты P&L (Прибыли и убытки) и Cash Flow (Денежный поток) по месяцам. Все расчеты производятся на основании данных вкладки "Monthly forecast" по заданным формулам. В этой вкладке ничего вносить не нужно.
B21: Вкладка "For Pitchdeck" | D21: В этой вкладке формируется таблица с динамикой выручки, операционной прибыли (EBITDA) и чистой прибыли по годам и строятся графики для лаконичной визуализации. Таблицу и график из этой вкладки можно скопировать на слайд с финансовой информацией питчдека вашего проекта для презентации инвесторам и партнерам.
B22: Вкладка "Cap Table" | D22: В этой вкладке вносится информация о всех держателях акций компании, привлеченных инвестициях по раундам, планируемой оценке стоимости компании и рассчитываются доли всех участников в динамике по раундам.
B23: Вкладка "Dividends" | D23: В этой вкладке рассчитываются начисленные дивиденды по годам для всех держателей акций компании исходя из прогнозируемой чистой прибыли в соответствии с долями, указанными на вкладке "Cap Table".
B24: Вкладка "Exit scenarios" | D24: В этой вкладке описывается предполагаемый сценарий выхода из компании (как пример приводится продажа компании в виде стратегического поглощения), задается планируемая стоимость продажи компании и предполагаемый год сделки. Рассчитывается доход каждого владельца акций компании при условии продажи всех акции, сумма вложенных инвестиций и ROI при выходе.
... B26: Вкладка "Data for Charts" | D26: Вспомогательная вкладка для упрощения создания графиков для вкладки "Charts". Вынесение данных, для которых необходима визуализация, на отдельную вкладку, помогает избежать ошибок и сделать модель понятнее как для команды проекта, так и для внешних партнеров (например, инвесторов). Все данные расчитываются по формулам на основании остальных вкладок. При необходимости, вы можете вынести сюда и другие метрики, по которым хотите постоить дополнительные графики для вашего бизнеса.

Sheet Settings
A2: GENERAL SETTINGS
A4: Company name | B4: Healthy4U
A5: Currency | B5: USD
A6: Country of incorporation | B6: Israel
A7: Income tax rate | B7: 0.23
A8: Payroll tax rate | B8: 0.35
A9: Tax Payment Month | B9: 3
A10: Cash in bank at start | B10: 0

Sheet Roadmap
A1: =Settings!$B$4 -> Healthy4U
A2: ROADMAP
A4: Growth driving events
B6: Type | C6: Date | D6: Months after seed round
A7: Incorporation | B7: incorporation | C7: 45139 | D7: 0
A8: B2B solution: MVP release | B8: new product | C8: 45884 | D8: 0
A9: B2B solution: 5 clients | B9: monetization | C9: 45899 | D9: 0
A10: Pre-seed round money transfer | B10: fundraising | C10: 45901 | D10: 0
A11: B2B solution: v.1 release | B11: new feature | C11: =if(D11>0,EDATE($C$10,D11),"not set") -> 45962 | D11: 2
A12: Android App for B2B | B12: new feature | C12: =if(D12>0,EDATE($C$11,D12),"not set") -> 46082 | D12: 4
A13: B2B solution: 50 clients | B13: monetization | C13: =if(D13>0,EDATE($C$11,D13),"not set") -> 46143 | D13: 6
A14: B2B solution: 100 clients | B14: fundraising | C14: =if(D14>0,EDATE($C$11,D14),"not set") -> 46235 | D14: 9
A15: Seed round money transfer | B15: fundraising | C15: =if(D15>0,EDATE($C$11,D15),"not set") -> 46266 | D15: 10
A16: EU expansion | B16: new region | C16: =if(D16>0,EDATE($C$11,D16),"not set") -> 46327 | D16: 12

Sheet Payroll
A1: =Settings!$B$4 -> Healthy4U
A2: PAYROLL
D4: Monthly salary | E4: Payroll taxes | F4: Monthly cost to company | G4: Annaul salary | H4: Start event in the roadmap | I4: Hire date | J4: Annual salary increase
A5: Administrative
A6: CEO | D6: 5000 | E6: =Settings!$B$8 -> 0.35 | F6: =D6/(1-E6) -> 7692.3077 | G6: =D6*12 -> 60000 | H6: Pre-seed round money transfer | I6: =IFERROR(VLOOKUP(H6,Roadmap!$A$7:$D$110,3,0),"not set, choose the event") -> 45901 | J6: 0.02 | K6: 12
A7: CFO | D7: 0 | E7: =Settings!$B$8 -> 0.35 | F7: =D7/(1-E7) -> 0 | G7: =D7*12 -> 0 | H7: B2B solution: 5 clients | I7: =IFERROR(VLOOKUP(H7,Roadmap!$A$7:$D$110,3,0),"not set, choose the event") -> 45899 | J7: 0 | K7: 12
A8: COO | D8: 0 | E8: =Settings!$B$8 -> 0.35 | F8: =D8/(1-E8) -> 0 | G8: =D8*12 -> 0 | H8: B2B solution: 100 clients | I8: =IFERROR(VLOOKUP(H8,Roadmap!$A$7:$D$110,3,0),"not set, choose the event") -> 46235 | J8: 0 | K8: 12
A9: HRD | D9: 0 | E9: =Settings!$B$8 -> 0.35 | F9: =D9/(1-E9) -> 0 | G9: =D9*12 -> 0 | I9: =IFERROR(VLOOKUP(H9,Roadmap!$A$7:$D$110,3,0),"not set, choose the event") -> not set, choose the event | J9: 0 | K9: 12
A10: Operations Coordinator / Office Manager | D10: 0 | E10: =Settings!$B$8 -> 0.35 | F10: =D10/(1-E10) -> 0 | G10: =D10*12 -> 0 | I10: =IFERROR(VLOOKUP(H10,Roadmap!$A$7:$D$110,3,0),"not set, choose the event") -> not set, choose the event | J10: 0 | K10: 12
A11: Employee 1 | D11: 0 | E11: =Settings!$B$8 -> 0.35 | F11: =D11/(1-E11) -> 0 | G11: =D11*12 -> 0 | I11: =IFERROR(VLOOKUP(H11,Roadmap!$A$7:$D$110,3,0),"not set, choose the event") -> not set, choose the event | J11: 0 | K11: 12
A12: Employee 2 | D12: 0 | E12: =Settings!$B$8 -> 0.35 | F12: =D12/(1-E12) -> 0 | G12: =D12*12 -> 0 | I12: =IFERROR(VLOOKUP(H12,Roadmap!$A$7:$D$110,3,0),"not set, choose the event") -> not set, choose the event | J12: 0 | K12: 12
A13: Employee 3 | D13: 0 | E13: =Settings!$B$8 -> 0.35 | F13: =D13/(1-E13) -> 0 | G13: =D13*12 -> 0 | I13: =IFERROR(VLOOKUP(H13,Roadmap!$A$7:$D$110,3,0),"not set, choose the event") -> not set, choose the event | J13: 0 | K13: 12
A14: Employee 4 | D14: 0 | E14: =Settings!$B$8 -> 0.35 | F14: =D14/(1-E14) -> 0 | G14: =D14*12 -> 0 | I14: =IFERROR(VLOOKUP(H14,Roadmap!$A$7:$D$110,3,0),"not set, choose the event") -> not set, choose the event | J14: 0 | K14: 12
A16: IT
A17: CTO | D17: 10000 | E17: =Settings!$B$8 -> 0.35 | F17: =D17/(1-E17) -> 15384.615 | G17: =D17*12 -> 120000 | H17: Seed round money transfer | I17: =IFERROR(VLOOKUP(H17,Roadmap!$A$7:$D$110,3,0),"not set, choose the event") -> 46266 | J17: 0 | K17: 12
A18: Developer frontend | D18: 4000 | E18: =Settings!$B$8 -> 0.35 | F18: =D18/(1-E18) -> 6153.8462 | G18: =D18*12 -> 48000 | H18: Seed round money transfer | I18: =IFERROR(VLOOKUP(H18,Roadmap!$A$7:$D$110,3,0),"not set, choose the event") -> 46266 | J18: 0.04 | K18: 12
A19: Developer backend | D19: 0 | E19: =Settings!$B$8 -> 0.35 | F19: =D19/(1-E19) -> 0 | G19: =D19*12 -> 0 | I19: =IFERROR(VLOOKUP(H19,Roadmap!$A$7:$D$110,3,0),"not set, choose the event") -> not set, choose the event | J19: 0 | K19: 12
A20: Developer fullstack | D20: 0 | E20: =Settings!$B$8 -> 0.35 | F20: =D20/(1-E20) -> 0 | G20: =D20*12 -> 0 | I20: =IFERROR(VLOOKUP(H20,Roadmap!$A$7:$D$110,3,0),"not set, choose the event") -> not set, choose the event | J20: 0 | K20: 12
A21: UX designer | D21: 3500 | E21: =Settings!$B$8 -> 0.35 | F21: =D21/(1-E21) -> 5384.6154 | G21: =D21*12 -> 42000 | I21: =IFERROR(VLOOKUP(H21,Roadmap!$A$7:$D$110,3,0),"not set, choose the event") -> not set, choose the event | J21: 0 | K21: 12
A22: Product manager | D22: 0 | E22: =Settings!$B$8 -> 0.35 | F22: =D22/(1-E22) -> 0 | G22: =D22*12 -> 0 | I22: =IFERROR(VLOOKUP(H22,Roadmap!$A$7:$D$110,3,0),"not set, choose the event") -> not set, choose the event | J22: 0 | K22: 12
A23: DevOps | D23: 0 | E23: =Settings!$B$8 -> 0.35 | F23: =D23/(1-E23) -> 0 | G23: =D23*12 -> 0 | I23: =IFERROR(VLOOKUP(H23,Roadmap!$A$7:$D$110,3,0),"not set, choose the event") -> not set, choose the event | J23: 0 | K23: 12
A24: Project Manager | D24: 0 | E24: =Settings!$B$8 -> 0.35 | F24: =D24/(1-E24) -> 0 | G24: =D24*12 -> 0 | I24: =IFERROR(VLOOKUP(H24,Roadmap!$A$7:$D$110,3,0),"not set, choose the event") -> not set, choose the event | J24: 0 | K24: 12
A25: Developer cross-platform | D25: 0 | E25: =Settings!$B$8 -> 0.35 | F25: =D25/(1-E25) -> 0 | G25: =D25*12 -> 0 | I25: =IFERROR(VLOOKUP(H25,Roadmap!$A$7:$D$110,3,0),"not set, choose the event") -> not set, choose the event | J25: 0 | K25: 12
A26: QA | D26: 0 | E26: =Settings!$B$8 -> 0.35 | F26: =D26/(1-E26) -> 0 | G26: =D26*12 -> 0 | I26: =IFERROR(VLOOKUP(H26,Roadmap!$A$7:$D$110,3,0),"not set, choose the event") -> not set, choose the event | J26: 0 | K26: 12
A27: Security engineer | D27: 0 | E27: =Settings!$B$8 -> 0.35 | F27: =D27/(1-E27) -> 0 | G27: =D27*12 -> 0 | I27: =IFERROR(VLOOKUP(H27,Roadmap!$A$7:$D$110,3,0),"not set, choose the event") -> not set, choose the event | J27: 0 | K27: 12
A28: Employee 4 | D28: 0 | E28: =Settings!$B$8 -> 0.35 | F28: =D28/(1-E28) -> 0 | G28: =D28*12 -> 0 | I28: =IFERROR(VLOOKUP(H28,Roadmap!$A$7:$D$110,3,0),"not set, choose the event") -> not set, choose the event | J28: 0 | K28: 12
A30: Marketing
A31: Head of Marketing | D31: 3000 | E31: =Settings!$B$8 -> 0.35 | F31: =D31/(1-E31) -> 4615.3846 | G31: =D31*12 -> 36000 | H31: Seed round money transfer | I31: =IFERROR(VLOOKUP(H31,Roadmap!$A$7:$D$110,3,0),"not set, choose the event") -> 46266 | J31: 0.04 | K31: 12
A32: Content Marketing Manager | D32: 0 | E32: =Settings!$B$8 -> 0.35 | F32: =D32/(1-E32) -> 0 | G32: =D32*12 -> 0 | I32: =IFERROR(VLOOKUP(H32,Roadmap!$A$7:$D$110,3,0),"not set, choose the event") -> not set, choose the event | J32: 0 | K32: 12
A33: Performance Marketing Manager | D33: 0 | E33: =Settings!$B$8 -> 0.35 | F33: =D33/(1-E33) -> 0 | G33: =D33*12 -> 0 | I33: =IFERROR(VLOOKUP(H33,Roadmap!$A$7:$D$110,3,0),"not set, choose the event") -> not set, choose the event | J33: 0 | K33: 12
A34: Community Manager / SMM | D34: 0 | E34: =Settings!$B$8 -> 0.35 | F34: =D34/(1-E34) -> 0 | G34: =D34*12 -> 0 | I34: =IFERROR(VLOOKUP(H34,Roadmap!$A$7:$D$110,3,0),"not set, choose the event") -> not set, choose the event | J34: 0 | K34: 12
A35: PR / Comms Manager | D35: 0 | E35: =Settings!$B$8 -> 0.35 | F35: =D35/(1-E35) -> 0 | G35: =D35*12 -> 0 | I35: =IFERROR(VLOOKUP(H35,Roadmap!$A$7:$D$110,3,0),"not set, choose the event") -> not set, choose the event | J35: 0 | K35: 12
A36: Marketing Designer | D36: 0 | E36: =Settings!$B$8 -> 0.35 | F36: =D36/(1-E36) -> 0 | G36: =D36*12 -> 0 | I36: =IFERROR(VLOOKUP(H36,Roadmap!$A$7:$D$110,3,0),"not set, choose the event") -> not set, choose the event | J36: 0 | K36: 12
A37: Employee 3 | D37: 0 | E37: =Settings!$B$8 -> 0.35 | F37: =D37/(1-E37) -> 0 | G37: =D37*12 -> 0 | I37: =IFERROR(VLOOKUP(H37,Roadmap!$A$7:$D$110,3,0),"not set, choose the event") -> not set, choose the event | J37: 0 | K37: 12
A38: Employee 4 | D38: 0 | E38: =Settings!$B$8 -> 0.35 | F38: =D38/(1-E38) -> 0 | G38: =D38*12 -> 0 | I38: =IFERROR(VLOOKUP(H38,Roadmap!$A$7:$D$110,3,0),"not set, choose the event") -> not set, choose the event | J38: 0 | K38: 12
A40: Sales
A41: Head of Sales | D41: 5000 | E41: =Settings!$B$8 -> 0.35 | F41: =D41/(1-E41) -> 7692.3077 | G41: =D41*12 -> 60000 | H41: Incorporation | I41: =IFERROR(VLOOKUP(H41,Roadmap!$A$7:$D$110,3,0),"not set, choose the event") -> 45139 | J41: 0.02 | K41: 12
A42: BDM | D42: 5000 | E42: =Settings!$B$8 -> 0.35 | F42: =D42/(1-E42) -> 7692.3077 | G42: =D42*12 -> 60000 | H42: Incorporation | I42: =IFERROR(VLOOKUP(H42,Roadmap!$A$7:$D$110,3,0),"not set, choose the event") -> 45139 | J42: 0.02 | K42: 12
A43: Partnerships Manager | D43: 1000 | E43: =Settings!$B$8 -> 0.35 | F43: =D43/(1-E43) -> 1538.4615 | G43: =D43*12 -> 12000 | H43: Incorporation | I43: =IFERROR(VLOOKUP(H43,Roadmap!$A$7:$D$110,3,0),"not set, choose the event") -> 45139 | J43: 0.02 | K43: 12
A44: Inbound Sales Manager | D44: 1000 | E44: =Settings!$B$8 -> 0.35 | F44: =D44/(1-E44) -> 1538.4615 | G44: =D44*12 -> 12000 | H44: Incorporation | I44: =IFERROR(VLOOKUP(H44,Roadmap!$A$7:$D$110,3,0),"not set, choose the event") -> 45139 | J44: 0.02 | K44: 12
...

Sheet Projections
A1: =Settings!$B$4 -> Healthy4U
A2: START
A4: INCORPORATION | B4: =Roadmap!C7 -> 45139
A5: SEED ROUND MONEY TRANSFER | B5: =Roadmap!C8 -> 45884
A7: REVENUE
A10: WEBSITE TRAFFIC
A12: Organic traffic | C12: Start event in the roadmap | D12: Date
A13: Traffic first month | B13: 1000 | C13: Incorporation | D13: =IFERROR(VLOOKUP(C13,Roadmap!$A$7:$D$110,3,0),"not set, choose the event") -> 45139
A14: Monthly increase | B14: 0.05
A15: Maximum traffic | B15: 100000
A17: Paid traffic
B18: Budget at start | C18: Start event in the roadmap | D18: Date | E18: Event in the roadmap to increase budget | F18: Date | G18: Additional budget | H18: Event in the roadmap to increase budget | I18: Date | J18: Additional budget | K18: Event in the roadmap to increase budget | L18: Date | M18: Additional budget
A19: Paid traffic marketing budget per month | B19: 1000 | C19: Incorporation | D19: =IFERROR(VLOOKUP(C19,Roadmap!$A$7:$D$110,3,0),"not set, choose the event") -> 45139 | E19: Seed round money transfer | F19: =IFERROR(VLOOKUP(E19,Roadmap!$A$7:$D$110,3,0),"not set, choose the event") -> 46266 | G19: 0 | I19: =IFERROR(VLOOKUP(H19,Roadmap!$A$7:$D$110,3,0),"not set, choose the event") -> not set, choose the event | J19: 0 | L19: =IFERROR(VLOOKUP(K19,Roadmap!$A$7:$D$110,3,0),"not set, choose the event") -> not set, choose the event | M19: 0
A21: CPC (Cost per click) | B21: 3
A22: Monthly decrease of Expected CPC | B22: 0.05
A23: Minimum Expected CPC | B23: 2
A25: BUSINESS MODEL: SUBSCRIPTION
A27: Pricing | C27: Start event in the roadmap | D27: Date
A28: Monthly subscription | B28: 100 | C28: Incorporation | D28: =IFERROR(VLOOKUP(C28,Roadmap!$A$7:$D$110,3,0),"not set, choose the event") -> 45139
A30: Expected monthly churn rate | B30: 0.15
A31: Expected LTV | B31: =iferror(B28/B30,0) -> 666.66667
A33: REVENUE STREAM 1: SELF-SERVICE
A35: Traffic conversion to subscription
A36: Conversion to subscription | B36: 0.005
A37: CAC - paid ads | B37: =B19/(B19/B21*B36) -> 600
A39: REVENUE STREAM 2: INBOUND SALES
B41: Start event in the roadmap | C41: Date
A42: Expected launch | B42: Incorporation | C42: =IFERROR(VLOOKUP(B42,Roadmap!$A$7:$D$110,3,0),"not set, choose the event") -> 45139
A44: Traffic conversion to lead
A45: Conversion to lead | B45: 0.1
A46: CPL (Cost Per Lead) | B46: =B19/(B19/B21*B45) -> 30
A48: Lead to subscription conversion
A49: Leads per Sales Manager per month | B49: 100
A50: Lead to sale conversion | B50: 0.1
A53: REVENUE STREAM 3: OUTBOUND SALES
B55: Start event in the roadmap | C55: Date
A56: Expected launch | B56: Incorporation | C56: =IFERROR(VLOOKUP(B56,Roadmap!$A$7:$D$110,3,0),"not set, choose the event") -> 45139
A58: Number of outbound sales managers first month | B58: 1
A59: Hiring frequency, months | B59: 3
A60: Max number of outbound sales managers | B60: 10
...

Sheet Charts
B1: =Settings!$B$4 -> Healthy4U
B2: KEY INDICATORS
B20: CAPITAL
C22: Months to reach break even | D22: =COUNTIF('P&L | Cash Flow | Balance'!28:28,"<=0") -> 8
C24: Capital required | D24: =iferror(-MIN('P&L | Cash Flow | Balance'!39:39),"-") -> 21252.97
B26: REVENUE

Sheet For Pitchdeck
C2: =YEAR('Monthly forecast'!E2) -> 2023 | D2: =C2+1 -> 2024 | E2: =D2+1 -> 2025 | F2: =E2+1 -> 2026 | G2: =F2+1 -> 2027 | I2: * Для слайда питчдека "Финансовый прогноз" ("Financial Forecast") скопируйте таблицу и графики на этом листе, которые показывают динамику выручки и прибыли по годам.
B3: ='P&L | Cash Flow | Balance'!A6 -> REVENUE | C3: =SUM(C4:C6) -> 29606.373 | D3: =SUM(D4:D6) -> 229756.58 | E3: =SUM(E4:E6) -> 444131.73 | F3: =SUM(F4:F6) -> 723504.46 | G3: =SUM(G4:G6) -> 1145002.3
B4: ='P&L | Cash Flow | Balance'!A7 -> REVENUE STREAM 1: SELF-SERVICE | C4: =SUMIFS('P&L | Cash Flow | Balance'!D7:CW7,'P&L | Cash Flow | Balance'!D2:CW2,">="&DATE(C2,1,1),'P&L | Cash Flow | Balance'!D2:CW2,"<="&DATE(C2,12,31)) -> 8857.6073 | D4: =SUMIFS('P&L | Cash Flow | Balance'!E7:CX7,'P&L | Cash Flow | Balance'!E2:CX2,">="&DATE(D2,1,1),'P&L | Cash Flow | Balance'!E2:CX2,"<="&DATE(D2,12,31)) -> 62911.87 | E4: =SUMIFS('P&L | Cash Flow | Balance'!F7:CY7,'P&L | Cash Flow | Balance'!F2:CY2,">="&DATE(E2,1,1),'P&L | Cash Flow | Balance'!F2:CY2,"<="&DATE(E2,12,31)) -> 114345.44 | F4: =SUMIFS('P&L | Cash Flow | Balance'!G7:CZ7,'P&L | Cash Flow | Balance'!G2:CZ2,">="&DATE(F2,1,1),'P&L | Cash Flow | Balance'!G2:CZ2,"<="&DATE(F2,12,31)) -> 191848.79 | G4: =SUMIFS('P&L | Cash Flow | Balance'!H7:DA7,'P&L | Cash Flow | Balance'!H2:DA2,">="&DATE(G2,1,1),'P&L | Cash Flow | Balance'!H2:DA2,"<="&DATE(G2,12,31)) -> 328905.06
B5: ='P&L | Cash Flow | Balance'!A8 -> REVENUE STREAM 2: INBOUND SALES | C5: =SUMIFS('P&L | Cash Flow | Balance'!D8:CW8,'P&L | Cash Flow | Balance'!D2:CW2,">="&DATE(C2,1,1),'P&L | Cash Flow | Balance'!D2:CW2,"<="&DATE(C2,12,31)) -> 17715.215 | D5: =SUMIFS('P&L | Cash Flow | Balance'!E8:CX8,'P&L | Cash Flow | Balance'!E2:CX2,">="&DATE(D2,1,1),'P&L | Cash Flow | Balance'!E2:CX2,"<="&DATE(D2,12,31)) -> 125823.74 | E5: =SUMIFS('P&L | Cash Flow | Balance'!F8:CY8,'P&L | Cash Flow | Balance'!F2:CY2,">="&DATE(E2,1,1),'P&L | Cash Flow | Balance'!F2:CY2,"<="&DATE(E2,12,31)) -> 228690.88 | F5: =SUMIFS('P&L | Cash Flow | Balance'!G8:CZ8,'P&L | Cash Flow | Balance'!G2:CZ2,">="&DATE(F2,1,1),'P&L | Cash Flow | Balance'!G2:CZ2,"<="&DATE(F2,12,31)) -> 383697.59 | G5: =SUMIFS('P&L | Cash Flow | Balance'!H8:DA8,'P&L | Cash Flow | Balance'!H2:DA2,">="&DATE(G2,1,1),'P&L | Cash Flow | Balance'!H2:DA2,"<="&DATE(G2,12,31)) -> 657810.13
B6: ='P&L | Cash Flow | Balance'!A9 -> REVENUE STREAM 3: OUTBOUND SALES | C6: =SUMIFS('P&L | Cash Flow | Balance'!D9:CW9,'P&L | Cash Flow | Balance'!D2:CW2,">="&DATE(C2,1,1),'P&L | Cash Flow | Balance'!D2:CW2,"<="&DATE(C2,12,31)) -> 3033.5512 | D6: =SUMIFS('P&L | Cash Flow | Balance'!E9:CX9,'P&L | Cash Flow | Balance'!E2:CX2,">="&DATE(D2,1,1),'P&L | Cash Flow | Balance'!E2:CX2,"<="&DATE(D2,12,31)) -> 41020.972 | E6: =SUMIFS('P&L | Cash Flow | Balance'!F9:CY9,'P&L | Cash Flow | Balance'!F2:CY2,">="&DATE(E2,1,1),'P&L | Cash Flow | Balance'!F2:CY2,"<="&DATE(E2,12,31)) -> 101095.42 | F6: =SUMIFS('P&L | Cash Flow | Balance'!G9:CZ9,'P&L | Cash Flow | Balance'!G2:CZ2,">="&DATE(F2,1,1),'P&L | Cash Flow | Balance'!G2:CZ2,"<="&DATE(F2,12,31)) -> 147958.08 | G6: =SUMIFS('P&L | Cash Flow | Balance'!H9:DA9,'P&L | Cash Flow | Balance'!H2:DA2,">="&DATE(G2,1,1),'P&L | Cash Flow | Balance'!H2:DA2,"<="&DATE(G2,12,31)) -> 158287.14
B7: ='P&L | Cash Flow | Balance'!A17 -> EBITDA | C7: =SUMIFS('P&L | Cash Flow | Balance'!D17:CW17,'P&L | Cash Flow | Balance'!D2:CW2,">="&DATE(C2,1,1),'P&L | Cash Flow | Balance'!D2:CW2,"<="&DATE(C2,12,31)) -> -6666.4336 | D7: =SUMIFS('P&L | Cash Flow | Balance'!E17:CX17,'P&L | Cash Flow | Balance'!E2:CX2,">="&DATE(D2,1,1),'P&L | Cash Flow | Balance'!E2:CX2,"<="&DATE(D2,12,31)) -> 125171.58 | E7: =SUMIFS('P&L | Cash Flow | Balance'!F17:CY17,'P&L | Cash Flow | Balance'!F2:CY2,">="&DATE(E2,1,1),'P&L | Cash Flow | Balance'!F2:CY2,"<="&DATE(E2,12,31)) -> 274424.4 | F7: =SUMIFS('P&L | Cash Flow | Balance'!G17:CZ17,'P&L | Cash Flow | Balance'!G2:CZ2,">="&DATE(F2,1,1),'P&L | Cash Flow | Balance'!G2:CZ2,"<="&DATE(F2,12,31)) -> 213613.03 | G7: =SUMIFS('P&L | Cash Flow | Balance'!H17:DA17,'P&L | Cash Flow | Balance'!H2:DA2,">="&DATE(G2,1,1),'P&L | Cash Flow | Balance'!H2:DA2,"<="&DATE(G2,12,31)) -> 237514.21
B8: ='P&L | Cash Flow | Balance'!A28 -> Net income | C8: =SUMIFS('P&L | Cash Flow | Balance'!D28:CW28,'P&L | Cash Flow | Balance'!D2:CW2,">="&DATE(C2,1,1),'P&L | Cash Flow | Balance'!D2:CW2,"<="&DATE(C2,12,31)) -> -9535.3768 | D8: =SUMIFS('P&L | Cash Flow | Balance'!E28:CX28,'P&L | Cash Flow | Balance'!E2:CX2,">="&DATE(D2,1,1),'P&L | Cash Flow | Balance'!E2:CX2,"<="&DATE(D2,12,31)) -> 91762.113 | E8: =SUMIFS('P&L | Cash Flow | Balance'!F28:CY28,'P&L | Cash Flow | Balance'!F2:CY2,">="&DATE(E2,1,1),'P&L | Cash Flow | Balance'!F2:CY2,"<="&DATE(E2,12,31)) -> 208098.45 | F8: =SUMIFS('P&L | Cash Flow | Balance'!G28:CZ28,'P&L | Cash Flow | Balance'!G2:CZ2,">="&DATE(F2,1,1),'P&L | Cash Flow | Balance'!G2:CZ2,"<="&DATE(F2,12,31)) -> 159822.02 | G8: =SUMIFS('P&L | Cash Flow | Balance'!H28:DA28,'P&L | Cash Flow | Balance'!H2:DA2,">="&DATE(G2,1,1),'P&L | Cash Flow | Balance'!H2:DA2,"<="&DATE(G2,12,31)) -> 176469.28

Sheet Monthly forecast
A1: =Settings!B4 -> Healthy4U
A2: Month | B2: Expense category | D2: =EDATE(E2,-1) -> 45108 | E2: =Projections!$B$4 -> 45139 | F2: =EDATE(E2,1) -> 45170 | G2: =EDATE(F2,1) -> 45200 | H2: =EDATE(G2,1) -> 45231 | I2: =EDATE(H2,1) -> 45261 | J2: =EDATE(I2,1) -> 45292 | K2: =EDATE(J2,1) -> 45323 | L2: =EDATE(K2,1) -> 45352 | M2: =EDATE(L2,1) -> 45383 | ... CX2: =EDATE(CW2,1) -> 48092
A4: REVENUE
A6: KEY INDICATORS
A8: Traffic | Z8: =N8*(1+Projections!$B$14) -> 0
A9: Organic traffic | E9: =IF(E2=Projections!$D$13,Projections!$B$13,IF(E2>Projections!$D$13,MIN(D9*(1+Projections!$B$14),Projections!$B$15),0)) -> 1000 | F9: =IF(F2=Projections!$D$13,Projections!$B$13,IF(F2>Projections!$D$13,MIN(E9*(1+Projections!$B$14),Projections!$B$15),0)) -> 1050 | G9: =IF(G2=Projections!$D$13,Projections!$B$13,IF(G2>Projections!$D$13,MIN(F9*(1+Projections!$B$14),Projections!$B$15),0)) -> 1102.5 | H9: =IF(H2=Projections!$D$13,Projections!$B$13,IF(H2>Projections!$D$13,MIN(G9*(1+Projections!$B$14),Projections!$B$15),0)) -> 1157.625 | I9: =IF(I2=Projections!$D$13,Projections!$B$13,IF(I2>Projections!$D$13,MIN(H9*(1+Projections!$B$14),Projections!$B$15),0)) -> 1215.5062 | J9: =IF(J2=Projections!$D$13,Projections!$B$13,IF(J2>Projections!$D$13,MIN(I9*(1+Projections!$B$14),Projections!$B$15),0)) -> 1276.2816 | K9: =IF(K2=Projections!$D$13,Projections!$B$13,IF(K2>Projections!$D$13,MIN(J9*(1+Projections!$B$14),Projections!$B$15),0)) -> 1340.0956 | L9: =IF(L2=Projections!$D$13,Projections!$B$13,IF(L2>Projections!$D$13,MIN(K9*(1+Projections!$B$14),Projections!$B$15),0)) -> 1407.1004 | ... CX9: =IF(CX2=Projections!$D$13,Projections!$B$13,IF(CX2>Projections!$D$13,MIN(CW9*(1+Projections!$B$14),Projections!$B$15),0)) -> 100000
A10: CPC | E10: =IF(E2=Projections!$D$19,Projections!$B$21,IF(E2>Projections!$D$19,MAX(Projections!$B$23,D10*(1-Projections!$B$22)),0)) -> 3 | F10: =IF(F2=Projections!$D$19,Projections!$B$21,IF(F2>Projections!$D$19,MAX(Projections!$B$23,E10*(1-Projections!$B$22)),0)) -> 2.85 | G10: =IF(G2=Projections!$D$19,Projections!$B$21,IF(G2>Projections!$D$19,MAX(Projections!$B$23,F10*(1-Projections!$B$22)),0)) -> 2.7075 | H10: =IF(H2=Projections!$D$19,Projections!$B$21,IF(H2>Projections!$D$19,MAX(Projections!$B$23,G10*(1-Projections!$B$22)),0)) -> 2.572125 | I10: =IF(I2=Projections!$D$19,Projections!$B$21,IF(I2>Projections!$D$19,MAX(Projections!$B$23,H10*(1-Projections!$B$22)),0)) -> 2.4435187 | J10: =IF(J2=Projections!$D$19,Projections!$B$21,IF(J2>Projections!$D$19,MAX(Projections!$B$23,I10*(1-Projections!$B$22)),0)) -> 2.3213428 | K10: =IF(K2=Projections!$D$19,Projections!$B$21,IF(K2>Projections!$D$19,MAX(Projections!$B$23,J10*(1-Projections!$B$22)),0)) -> 2.2052757 | L10: =IF(L2=Projections!$D$19,Projections!$B$21,IF(L2>Projections!$D$19,MAX(Projections!$B$23,K10*(1-Projections!$B$22)),0)) -> 2.0950119 | ... CX10: =IF(CX2=Projections!$D$19,Projections!$B$21,IF(CX2>Projections!$D$19,MAX(Projections!$B$23,CW10*(1-Projections!$B$22)),0)) -> 2
A11: Paid traffic | E11: =IFERROR(E65/E10,0) -> 333.33333 | F11: =IFERROR(F65/F10,0) -> 350.87719 | G11: =IFERROR(G65/G10,0) -> 369.34441 | H11: =IFERROR(H65/H10,0) -> 388.78359 | I11: =IFERROR(I65/I10,0) -> 409.24589 | J11: =IFERROR(J65/J10,0) -> 430.78514 | K11: =IFERROR(K65/K10,0) -> 453.45805 | L11: =IFERROR(L65/L10,0) -> 477.32426 | ... CX11: =IFERROR(CX65/CX10,0) -> 500
A12: Total traffic | E12: =SUM(E9:E11) -> 1336.3333 | F12: =SUM(F9:F11) -> 1403.7272 | G12: =SUM(G9:G11) -> 1474.5519 | H12: =SUM(H9:H11) -> 1548.9807 | I12: =SUM(I9:I11) -> 1627.1957 | J12: =SUM(J9:J11) -> 1709.3881 | K12: =SUM(K9:K11) -> 1795.759 | L12: =SUM(L9:L11) -> 1886.5197 | ... CX12: =SUM(CX9:CX11) -> 100502
A15: =Projections!A33 -> REVENUE STREAM 1: SELF-SERVICE
A17: New subscribers | E17: =if(E2>=Projections!$D$28,E12*Projections!$B$36,0) -> 6.6816667 | F17: =if(F2>=Projections!$D$28,F12*Projections!$B$36,0) -> 7.018636 | G17: =if(G2>=Projections!$D$28,G12*Projections!$B$36,0) -> 7.3727596 | H17: =if(H2>=Projections!$D$28,H12*Projections!$B$36,0) -> 7.7449036 | I17: =if(I2>=Projections!$D$28,I12*Projections!$B$36,0) -> 8.1359783 | J17: =if(J2>=Projections!$D$28,J12*Projections!$B$36,0) -> 8.5469403 | K17: =if(K2>=Projections!$D$28,K12*Projections!$B$36,0) -> 8.9787948 | L17: =if(L2>=Projections!$D$28,L12*Projections!$B$36,0) -> 9.4325985 | ... CX17: =if(CX2>=Projections!$D$28,CX12*Projections!$B$36,0) -> 502.51
A18: Churn rate | E18: =IF(E2>=Projections!$D$28,Projections!$B$30,0) -> 0.15 | F18: =IF(F2>=Projections!$D$28,Projections!$B$30,0) -> 0.15 | G18: =IF(G2>=Projections!$D$28,Projections!$B$30,0) -> 0.15 | H18: =IF(H2>=Projections!$D$28,Projections!$B$30,0) -> 0.15 | I18: =IF(I2>=Projections!$D$28,Projections!$B$30,0) -> 0.15 | J18: =IF(J2>=Projections!$D$28,Projections!$B$30,0) -> 0.15 | K18: =IF(K2>=Projections!$D$28,Projections!$B$30,0) -> 0.15 | L18: =IF(L2>=Projections!$D$28,Projections!$B$30,0) -> 0.15 | ... CX18: =IF(CX2>=Projections!$D$28,Projections!$B$30,0) -> 0.15
A19: Lost subscribers | E19: =D20*E18 -> 0 | F19: =E20*F18 -> 1.00225 | G19: =F20*G18 -> 1.9047079 | H19: =G20*H18 -> 2.7249156 | I19: =H20*I18 -> 3.4779138 | J19: =I20*J18 -> 4.1766235 | K19: =J20*K18 -> 4.832171 | L19: =K20*L18 -> 5.4541646 | ... CX19: =CW20*CX18 -> 420.41958
A20: Subscribers - End of the period | E20: =D20+E17-E19 -> 6.6816667 | F20: =E20+F17-F19 -> 12.698053 | G20: =F20+G17-G19 -> 18.166104 | H20: =G20+H17-H19 -> 23.186092 | I20: =H20+I17-I19 -> 27.844157 | J20: =I20+J17-J19 -> 32.214473 | K20: =J20+K17-K19 -> 36.361097 | L20: =K20+L17-L19 -> 40.339531 | ... CX20: =CW20+CX17-CX19 -> 2884.8876
A22: Gross revenue Self-service | E22: =E20*Projections!$B$28 -> 668.16667 | F22: =F20*Projections!$B$28 -> 1269.8053 | G22: =G20*Projections!$B$28 -> 1816.6104 | H22: =H20*Projections!$B$28 -> 2318.6092 | I22: =I20*Projections!$B$28 -> 2784.4157 | J22: =J20*Projections!$B$28 -> 3221.4473 | K22: =K20*Projections!$B$28 -> 3636.1097 | L22: =L20*Projections!$B$28 -> 4033.9531 | ... CX22: =CX20*Projections!$B$28 -> 288488.76
A24: =Projections!A39 -> REVENUE STREAM 2: INBOUND SALES
A26: Leads | E26: =if(E2>=Projections!$C$42,E12*Projections!$B$45,0) -> 133.63333 | F26: =if(F2>=Projections!$C$42,F12*Projections!$B$45,0) -> 140.37272 | G26: =if(G2>=Projections!$C$42,G12*Projections!$B$45,0) -> 147.45519 | H26: =if(H2>=Projections!$C$42,H12*Projections!$B$45,0) -> 154.89807 | I26: =if(I2>=Projections!$C$42,I12*Projections!$B$45,0) -> 162.71957 | J26: =if(J2>=Projections!$C$42,J12*Projections!$B$45,0) -> 170.93881 | K26: =if(K2>=Projections!$C$42,K12*Projections!$B$45,0) -> 179.5759 | L26: =if(L2>=Projections!$C$42,L12*Projections!$B$45,0) -> 188.65197 | ... CX26: =if(CX2>=Projections!$C$42,CX12*Projections!$B$45,0) -> 10050.2
A28: New subscribers | E28: =IFERROR(E26*Projections!$B$50,0) -> 13.363333 | F28: =IFERROR(F26*Projections!$B$50,0) -> 14.037272 | G28: =IFERROR(G26*Projections!$B$50,0) -> 14.745519 | H28: =IFERROR(H26*Projections!$B$50,0) -> 15.489807 | I28: =IFERROR(I26*Projections!$B$50,0) -> 16.271957 | J28: =IFERROR(J26*Projections!$B$50,0) -> 17.093881 | K28: =IFERROR(K26*Projections!$B$50,0) -> 17.95759 | L28: =IFERROR(L26*Projections!$B$50,0) -> 18.865197 | ... CX28: =IFERROR(CX26*Projections!$B$50,0) -> 1005.02
A29: Churn rate | E29: =IF(E2>=Projections!$D$28,Projections!$B$30,0) -> 0.15 | F29: =IF(F2>=Projections!$D$28,Projections!$B$30,0) -> 0.15 | G29: =IF(G2>=Projections!$D$28,Projections!$B$30,0) -> 0.15 | H29: =IF(H2>=Projections!$D$28,Projections!$B$30,0) -> 0.15 | I29: =IF(I2>=Projections!$D$28,Projections!$B$30,0) -> 0.15 | J29: =IF(J2>=Projections!$D$28,Projections!$B$30,0) -> 0.15 | K29: =IF(K2>=Projections!$D$28,Projections!$B$30,0) -> 0.15 | L29: =IF(L2>=Projections!$D$28,Projections!$B$30,0) -> 0.15 | ... CX29: =IF(CX2>=Projections!$D$28,Projections!$B$30,0) -> 0.15
A30: Lost subscribers | E30: =D31*E29 -> 0 | F30: =E31*F29 -> 2.0045 | G30: =F31*G29 -> 3.8094158 | H30: =G31*H29 -> 5.4498313 | I30: =H31*I29 -> 6.9558277 | J30: =I31*J29 -> 8.353247 | K30: =J31*K29 -> 9.664342 | L30: =K31*L29 -> 10.908329 | ... CX30: =CW31*CX29 -> 840.83915
A31: Subscribers - End of the period | E31: =D31+E28-E30 -> 13.363333 | F31: =E31+F28-F30 -> 25.396105 | G31: =F31+G28-G30 -> 36.332209 | H31: =G31+H28-H30 -> 46.372185 | I31: =H31+I28-I30 -> 55.688313 | J31: =I31+J28-J30 -> 64.428947 | K31: =J31+K28-K30 -> 72.722194 | L31: =K31+L28-L30 -> 80.679062 | ... CX31: =CW31+CX28-CX30 -> 5769.7752
A33: Gross revenue Inbound Sales | E33: =E31*Projections!$B$28 -> 1336.3333 | F33: =F31*Projections!$B$28 -> 2539.6105 | G33: =G31*Projections!$B$28 -> 3633.2209 | H33: =H31*Projections!$B$28 -> 4637.2185 | I33: =I31*Projections!$B$28 -> 5568.8313 | J33: =J31*Projections!$B$28 -> 6442.8947 | K33: =K31*Projections!$B$28 -> 7272.2194 | L33: =L31*Projections!$B$28 -> 8067.9062 | ... CX33: =CX31*Projections!$B$28 -> 576977.52
A35: =Projections!A53 -> REVENUE STREAM 3: OUTBOUND SALES
A37: New subscribers | E37: =E87*Projections!$B$62 -> 2 | F37: =F87*Projections!$B$62 -> 2 | G37: =G87*Projections!$B$62 -> 2 | H37: =H87*Projections!$B$62 -> 4 | I37: =I87*Projections!$B$62 -> 4 | J37: =J87*Projections!$B$62 -> 4 | K37: =K87*Projections!$B$62 -> 6 | L37: =L87*Projections!$B$62 -> 6 | ... CX37: =CX87*Projections!$B$62 -> 20
A38: Churn rate | E38: =IF(E2>=Projections!$D$28,Projections!$B$30,0) -> 0.15 | F38: =IF(F2>=Projections!$D$28,Projections!$B$30,0) -> 0.15 | G38: =IF(G2>=Projections!$D$28,Projections!$B$30,0) -> 0.15 | H38: =IF(H2>=Projections!$D$28,Projections!$B$30,0) -> 0.15 | I38: =IF(I2>=Projections!$D$28,Projections!$B$30,0) -> 0.15 | J38: =IF(J2>=Projections!$D$28,Projections!$B$30,0) -> 0.15 | K38: =IF(K2>=Projections!$D$28,Projections!$B$30,0) -> 0.15 | L38: =IF(L2>=Projections!$D$28,Projections!$B$30,0) -> 0.15 | ... CX38: =IF(CX2>=Projections!$D$28,Projections!$B$30,0) -> 0.15
A39: Lost subscribers | E39: =D40*E38 -> 0 | F39: =E40*F38 -> 0.3 | G39: =F40*G38 -> 0.555 | H39: =G40*H38 -> 0.77175 | I39: =H40*I38 -> 1.2559875 | J39: =I40*J38 -> 1.6675894 | K39: =J40*K38 -> 2.017451 | L39: =K40*L38 -> 2.6148333 | ... CX39: =CW40*CX38 -> 19.999941
A40: Subscribers - End of the period | E40: =D40+E37-E39 -> 2 | F40: =E40+F37-F39 -> 3.7 | G40: =F40+G37-G39 -> 5.145 | H40: =G40+H37-H39 -> 8.37325 | I40: =H40+I37-I39 -> 11.117263 | J40: =I40+J37-J39 -> 13.449673 | K40: =J40+K37-K39 -> 17.432222 | L40: =K40+L37-L39 -> 20.817389 | ... CX40: =CW40+CX37-CX39 -> 133.333
A42: Gross revenue Outbound Sales | E42: =E40*Projections!$B$28 -> 200 | F42: =F40*Projections!$B$28 -> 370 | G42: =G40*Projections!$B$28 -> 514.5 | H42: =H40*Projections!$B$28 -> 837.325 | I42: =I40*Projections!$B$28 -> 1111.7262 | J42: =J40*Projections!$B$28 -> 1344.9673 | K42: =K40*Projections!$B$28 -> 1743.2222 | L42: =L40*Projections!$B$28 -> 2081.7389 | ... CX42: =CX40*Projections!$B$28 -> 13333.3
A44: Total subscribers - End of the period | E44: =E40+E31+E20 -> 22.045 | F44: =F40+F31+F20 -> 41.794158 | G44: =G40+G31+G20 -> 59.643313 | H44: =H40+H31+H20 -> 77.931527 | I44: =I40+I31+I20 -> 94.649733 | J44: =J40+J31+J20 -> 110.09309 | K44: =K40+K31+K20 -> 126.51551 | L44: =L40+L31+L20 -> 141.83598 | ... CX44: =CX40+CX31+CX20 -> 8787.9958
A45: Total gross revenue | E45: =E42+E33+E22 -> 2204.5 | F45: =F42+F33+F22 -> 4179.4158 | G45: =G42+G33+G22 -> 5964.3313 | H45: =H42+H33+H22 -> 7793.1527 | I45: =I42+I33+I22 -> 9464.9733 | J45: =J42+J33+J22 -> 11009.309 | K45: =K42+K33+K22 -> 12651.551 | L45: =L42+L33+L22 -> 14183.598 | ... CX45: =CX42+CX33+CX22 -> 878799.58
A47: COGS | E47: =SUM(E49:E50) -> 66.135 | F47: =SUM(F49:F50) -> 125.38247 | G47: =SUM(G49:G50) -> 178.92994 | H47: =SUM(H49:H50) -> 233.79458 | I47: =SUM(I49:I50) -> 283.9492 | J47: =SUM(J49:J50) -> 330.27928 | K47: =SUM(K49:K50) -> 379.54654 | L47: =SUM(L49:L50) -> 425.50795 | ... CX47: =SUM(CX49:CX50) -> 26363.987
A49: Hosting | E49: =E44*Projections!$B$68 -> 44.09 | F49: =F44*Projections!$B$68 -> 83.588316 | G49: =G44*Projections!$B$68 -> 119.28663 | H49: =H44*Projections!$B$68 -> 155.86305 | I49: =I44*Projections!$B$68 -> 189.29947 | J49: =J44*Projections!$B$68 -> 220.18619 | K49: =K44*Projections!$B$68 -> 253.03103 | L49: =L44*Projections!$B$68 -> 283.67196 | ... CX49: =CX44*Projections!$B$68 -> 17575.992
A50: Payments processing | E50: =E45*Projections!$B$67 -> 22.045 | F50: =F45*Projections!$B$67 -> 41.794158 | G50: =G45*Projections!$B$67 -> 59.643313 | H50: =H45*Projections!$B$67 -> 77.931527 | I50: =I45*Projections!$B$67 -> 94.649733 | J50: =J45*Projections!$B$67 -> 110.09309 | K50: =K45*Projections!$B$67 -> 126.51551 | L50: =L45*Projections!$B$67 -> 141.83598 | ... CX50: =CX45*Projections!$B$67 -> 8787.9958
A53: SG&A | E53: =E55+E79+E91+E139+E151 -> 7076.9231 | F53: =F55+F79+F91+F139+F151 -> 7076.9231 | G53: =G55+G79+G91+G139+G151 -> 7076.9231 | H53: =H55+H79+H91+H139+H151 -> 7076.9231 | I53: =I55+I79+I91+I139+I151 -> 7076.9231 | J53: =J55+J79+J91+J139+J151 -> 7076.9231 | K53: =K55+K79+K91+K139+K151 -> 7076.9231 | L53: =L55+L79+L91+L139+L151 -> 7076.9231 | ... CX53: =CX55+CX79+CX91+CX139+CX151 -> 240053.82
A55: MARKETING | E55: =E57+E65+E68 -> 1000 | F55: =F57+F65+F68 -> 1000 | G55: =G57+G65+G68 -> 1000 | H55: =H57+H65+H68 -> 1000 | I55: =I57+I65+I68 -> 1000 | J55: =J57+J65+J68 -> 1000 | K55: =K57+K65+K68 -> 1000 | L55: =L57+L65+L68 -> 1000 | ... CX55: =CX57+CX65+CX68 -> 4000
A57: =Projections!A75 -> Brand awareness campaigns | B57: Marketing | E57: =SUM(E58:E60) -> 0 | F57: =SUM(F58:F60) -> 0 | G57: =SUM(G58:G60) -> 0 | H57: =SUM(H58:H60) -> 0 | I57: =SUM(I58:I60) -> 0 | J57: =SUM(J58:J60) -> 0 | K57: =SUM(K58:K60) -> 0 | L57: =SUM(L58:L60) -> 0 | ... CX57: =SUM(CX58:CX60) -> 3000
A58: =Projections!A76 -> Channel 1 | E58: =IF(E$2<Projections!$D76,0,IF(and(E$2>=Projections!$D76,E$2<Projections!$F76),Projections!$B76,if(and(E$2>=Projections!$F76,E$2<Projections!$I76),Projections!$B76+Projections!$G76,if(and(E$2>=Projections!$I76,E$2<Projections!$L76),Projections!$B76+Projections!$G76+Projections!$J76,IF(E$2>=Projections!$L76,Projections!$B76+Projections!$G76+Projections!$J76+Projections!$M76,""))))) -> 0 | F58: =IF(F$2<Projections!$D76,0,IF(and(F$2>=Projections!$D76,F$2<Projections!$F76),Projections!$B76,if(and(F$2>=Projections!$F76,F$2<Projections!$I76),Projections!$B76+Projections!$G76,if(and(F$2>=Projections!$I76,F$2<Projections!$L76),Projections!$B76+Projections!$G76+Projections!$J76,IF(F$2>=Projections!$L76,Projections!$B76+Projections!$G76+Projections!$J76+Projections!$M76,""))))) -> 0 | G58: =IF(G$2<Projections!$D76,0,IF(and(G$2>=Projections!$D76,G$2<Projections!$F76),Projections!$B76,if(and(G$2>=Projections!$F76,G$2<Projections!$I76),Projections!$B76+Projections!$G76,if(and(G$2>=Projections!$I76,G$2<Projections!$L76),Projections!$B76+Projections!$G76+Projections!$J76,IF(G$2>=Projections!$L76,Projections!$B76+Projections!$G76+Projections!$J76+Projections!$M76,""))))) -> 0 | H58: =IF(H$2<Projections!$D76,0,IF(and(H$2>=Projections!$D76,H$2<Projections!$F76),Projections!$B76,if(and(H$2>=Projections!$F76,H$2<Projections!$I76),Projections!$B76+Projections!$G76,if(and(H$2>=Projections!$I76,H$2<Projections!$L76),Projections!$B76+Projections!$G76+Projections!$J76,IF(H$2>=Projections!$L76,Projections!$B76+Projections!$G76+Projections!$J76+Projections!$M76,""))))) -> 0 | I58: =IF(I$2<Projections!$D76,0,IF(and(I$2>=Projections!$D76,I$2<Projections!$F76),Projections!$B76,if(and(I$2>=Projections!$F76,I$2<Projections!$I76),Projections!$B76+Projections!$G76,if(and(I$2>=Projections!$I76,I$2<Projections!$L76),Projections!$B76+Projections!$G76+Projections!$J76,IF(I$2>=Projections!$L76,Projections!$B76+Projections!$G76+Projections!$J76+Projections!$M76,""))))) -> 0 | J58: =IF(J$2<Projections!$D76,0,IF(and(J$2>=Projections!$D76,J$2<Projections!$F76),Projections!$B76,if(and(J$2>=Projections!$F76,J$2<Projections!$I76),Projections!$B76+Projections!$G76,if(and(J$2>=Projections!$I76,J$2<Projections!$L76),Projections!$B76+Projections!$G76+Projections!$J76,IF(J$2>=Projections!$L76,Projections!$B76+Projections!$G76+Projections!$J76+Projections!$M76,""))))) -> 0 | K58: =IF(K$2<Projections!$D76,0,IF(and(K$2>=Projections!$D76,K$2<Projections!$F76),Projections!$B76,if(and(K$2>=Projections!$F76,K$2<Projections!$I76),Projections!$B76+Projections!$G76,if(and(K$2>=Projections!$I76,K$2<Projections!$L76),Projections!$B76+Projections!$G76+Projections!$J76,IF(K$2>=Projections!$L76,Projections!$B76+Projections!$G76+Projections!$J76+Projections!$M76,""))))) -> 0 | L58: =IF(L$2<Projections!$D76,0,IF(and(L$2>=Projections!$D76,L$2<Projections!$F76),Projections!$B76,if(and(L$2>=Projections!$F76,L$2<Projections!$I76),Projections!$B76+Projections!$G76,if(and(L$2>=Projections!$I76,L$2<Projections!$L76),Projections!$B76+Projections!$G76+Projections!$J76,IF(L$2>=Projections!$L76,Projections!$B76+Projections!$G76+Projections!$J76+Projections!$M76,""))))) -> 0 | ... CX58: =IF(CX$2<Projections!$D76,0,IF(and(CX$2>=Projections!$D76,CX$2<Projections!$F76),Projections!$B76,if(and(CX$2>=Projections!$F76,CX$2<Projections!$I76),Projections!$B76+Projections!$G76,if(and(CX$2>=Projections!$I76,CX$2<Projections!$L76),Projections!$B76+Projections!$G76+Projections!$J76,IF(CX$2>=Projections!$L76,Projections!$B76+Projections!$G76+Projections!$J76+Projections!$M76,""))))) -> 3000
A59: =Projections!A77 -> Channel 2 | E59: =IF(E$2<Projections!$D77,0,IF(and(E$2>=Projections!$D77,E$2<Projections!$F77),Projections!$B77,if(and(E$2>=Projections!$F77,E$2<Projections!$I77),Projections!$B77+Projections!$G77,if(and(E$2>=Projections!$I77,E$2<Projections!$L77),Projections!$B77+Projections!$G77+Projections!$J77,IF(E$2>=Projections!$L77,Projections!$B77+Projections!$G77+Projections!$J77+Projections!$M77,""))))) -> 0 | F59: =IF(F$2<Projections!$D77,0,IF(and(F$2>=Projections!$D77,F$2<Projections!$F77),Projections!$B77,if(and(F$2>=Projections!$F77,F$2<Projections!$I77),Projections!$B77+Projections!$G77,if(and(F$2>=Projections!$I77,F$2<Projections!$L77),Projections!$B77+Projections!$G77+Projections!$J77,IF(F$2>=Projections!$L77,Projections!$B77+Projections!$G77+Projections!$J77+Projections!$M77,""))))) -> 0 | G59: =IF(G$2<Projections!$D77,0,IF(and(G$2>=Projections!$D77,G$2<Projections!$F77),Projections!$B77,if(and(G$2>=Projections!$F77,G$2<Projections!$I77),Projections!$B77+Projections!$G77,if(and(G$2>=Projections!$I77,G$2<Projections!$L77),Projections!$B77+Projections!$G77+Projections!$J77,IF(G$2>=Projections!$L77,Projections!$B77+Projections!$G77+Projections!$J77+Projections!$M77,""))))) -> 0 | H59: =IF(H$2<Projections!$D77,0,IF(and(H$2>=Projections!$D77,H$2<Projections!$F77),Projections!$B77,if(and(H$2>=Projections!$F77,H$2<Projections!$I77),Projections!$B77+Projections!$G77,if(and(H$2>=Projections!$I77,H$2<Projections!$L77),Projections!$B77+Projections!$G77+Projections!$J77,IF(H$2>=Projections!$L77,Projections!$B77+Projections!$G77+Projections!$J77+Projections!$M77,""))))) -> 0 | I59: =IF(I$2<Projections!$D77,0,IF(and(I$2>=Projections!$D77,I$2<Projections!$F77),Projections!$B77,if(and(I$2>=Projections!$F77,I$2<Projections!$I77),Projections!$B77+Projections!$G77,if(and(I$2>=Projections!$I77,I$2<Projections!$L77),Projections!$B77+Projections!$G77+Projections!$J77,IF(I$2>=Projections!$L77,Projections!$B77+Projections!$G77+Projections!$J77+Projections!$M77,""))))) -> 0 | J59: =IF(J$2<Projections!$D77,0,IF(and(J$2>=Projections!$D77,J$2<Projections!$F77),Projections!$B77,if(and(J$2>=Projections!$F77,J$2<Projections!$I77),Projections!$B77+Projections!$G77,if(and(J$2>=Projections!$I77,J$2<Projections!$L77),Projections!$B77+Projections!$G77+Projections!$J77,IF(J$2>=Projections!$L77,Projections!$B77+Projections!$G77+Projections!$J77+Projections!$M77,""))))) -> 0 | K59: =IF(K$2<Projections!$D77,0,IF(and(K$2>=Projections!$D77,K$2<Projections!$F77),Projections!$B77,if(and(K$2>=Projections!$F77,K$2<Projections!$I77),Projections!$B77+Projections!$G77,if(and(K$2>=Projections!$I77,K$2<Projections!$L77),Projections!$B77+Projections!$G77+Projections!$J77,IF(K$2>=Projections!$L77,Projections!$B77+Projections!$G77+Projections!$J77+Projections!$M77,""))))) -> 0 | L59: =IF(L$2<Projections!$D77,0,IF(and(L$2>=Projections!$D77,L$2<Projections!$F77),Projections!$B77,if(and(L$2>=Projections!$F77,L$2<Projections!$I77),Projections!$B77+Projections!$G77,if(and(L$2>=Projections!$I77,L$2<Projections!$L77),Projections!$B77+Projections!$G77+Projections!$J77,IF(L$2>=Projections!$L77,Projections!$B77+Projections!$G77+Projections!$J77+Projections!$M77,""))))) -> 0 | ... CX59: =IF(CX$2<Projections!$D77,0,IF(and(CX$2>=Projections!$D77,CX$2<Projections!$F77),Projections!$B77,if(and(CX$2>=Projections!$F77,CX$2<Projections!$I77),Projections!$B77+Projections!$G77,if(and(CX$2>=Projections!$I77,CX$2<Projections!$L77),Projections!$B77+Projections!$G77+Projections!$J77,IF(CX$2>=Projections!$L77,Projections!$B77+Projections!$G77+Projections!$J77+Projections!$M77,""))))) -> 0
A60: =Projections!A78 -> Channel 3 | E60: =IF(E$2<Projections!$D78,0,IF(and(E$2>=Projections!$D78,E$2<Projections!$F78),Projections!$B78,if(and(E$2>=Projections!$F78,E$2<Projections!$I78),Projections!$B78+Projections!$G78,if(and(E$2>=Projections!$I78,E$2<Projections!$L78),Projections!$B78+Projections!$G78+Projections!$J78,IF(E$2>=Projections!$L78,Projections!$B78+Projections!$G78+Projections!$J78+Projections!$M78,""))))) -> 0 | F60: =IF(F$2<Projections!$D78,0,IF(and(F$2>=Projections!$D78,F$2<Projections!$F78),Projections!$B78,if(and(F$2>=Projections!$F78,F$2<Projections!$I78),Projections!$B78+Projections!$G78,if(and(F$2>=Projections!$I78,F$2<Projections!$L78),Projections!$B78+Projections!$G78+Projections!$J78,IF(F$2>=Projections!$L78,Projections!$B78+Projections!$G78+Projections!$J78+Projections!$M78,""))))) -> 0 | G60: =IF(G$2<Projections!$D78,0,IF(and(G$2>=Projections!$D78,G$2<Projections!$F78),Projections!$B78,if(and(G$2>=Projections!$F78,G$2<Projections!$I78),Projections!$B78+Projections!$G78,if(and(G$2>=Projections!$I78,G$2<Projections!$L78),Projections!$B78+Projections!$G78+Projections!$J78,IF(G$2>=Projections!$L78,Projections!$B78+Projections!$G78+Projections!$J78+Projections!$M78,""))))) -> 0 | H60: =IF(H$2<Projections!$D78,0,IF(and(H$2>=Projections!$D78,H$2<Projections!$F78),Projections!$B78,if(and(H$2>=Projections!$F78,H$2<Projections!$I78),Projections!$B78+Projections!$G78,if(and(H$2>=Projections!$I78,H$2<Projections!$L78),Projections!$B78+Projections!$G78+Projections!$J78,IF(H$2>=Projections!$L78,Projections!$B78+Projections!$G78+Projections!$J78+Projections!$M78,""))))) -> 0 | I60: =IF(I$2<Projections!$D78,0,IF(and(I$2>=Projections!$D78,I$2<Projections!$F78),Projections!$B78,if(and(I$2>=Projections!$F78,I$2<Projections!$I78),Projections!$B78+Projections!$G78,if(and(I$2>=Projections!$I78,I$2<Projections!$L78),Projections!$B78+Projections!$G78+Projections!$J78,IF(I$2>=Projections!$L78,Projections!$B78+Projections!$G78+Projections!$J78+Projections!$M78,""))))) -> 0 | J60: =IF(J$2<Projections!$D78,0,IF(and(J$2>=Projections!$D78,J$2<Projections!$F78),Projections!$B78,if(and(J$2>=Projections!$F78,J$2<Projections!$I78),Projections!$B78+Projections!$G78,if(and(J$2>=Projections!$I78,J$2<Projections!$L78),Projections!$B78+Projections!$G78+Projections!$J78,IF(J$2>=Projections!$L78,Projections!$B78+Projections!$G78+Projections!$J78+Projections!$M78,""))))) -> 0 | K60: =IF(K$2<Projections!$D78,0,IF(and(K$2>=Projections!$D78,K$2<Projections!$F78),Projections!$B78,if(and(K$2>=Projections!$F78,K$2<Projections!$I78),Projections!$B78+Projections!$G78,if(and(K$2>=Projections!$I78,K$2<Projections!$L78),Projections!$B78+Projections!$G78+Projections!$J78,IF(K$2>=Projections!$L78,Projections!$B78+Projections!$G78+Projections!$J78+Projections!$M78,""))))) -> 0 | L60: =IF(L$2<Projections!$D78,0,IF(and(L$2>=Projections!$D78,L$2<Projections!$F78),Projections!$B78,if(and(L$2>=Projections!$F78,L$2<Projections!$I78),Projections!$B78+Projections!$G78,if(and(L$2>=Projections!$I78,L$2<Projections!$L78),Projections!$B78+Projections!$G78+Projections!$J78,IF(L$2>=Projections!$L78,Projections!$B78+Projections!$G78+Projections!$J78+Projections!$M78,""))))) -> 0 | ... CX60: =IF(CX$2<Projections!$D78,0,IF(and(CX$2>=Projections!$D78,CX$2<Projections!$F78),Projections!$B78,if(and(CX$2>=Projections!$F78,CX$2<Projections!$I78),Projections!$B78+Projections!$G78,if(and(CX$2>=Projections!$I78,CX$2<Projections!$L78),Projections!$B78+Projections!$G78+Projections!$J78,IF(CX$2>=Projections!$L78,Projections!$B78+Projections!$G78+Projections!$J78+Projections!$M78,""))))) -> 0
A64: Direct response campaigns
...

Sheet Unit economics
A1: =Settings!B4 -> Healthy4U
A2: Month | C2: ='Monthly forecast'!D2 -> 45108 | D2: ='Monthly forecast'!E2 -> 45139 | E2: =EDATE(D2,1) -> 45170 | F2: =EDATE(E2,1) -> 45200 | G2: =EDATE(F2,1) -> 45231 | H2: =EDATE(G2,1) -> 45261 | I2: =EDATE(H2,1) -> 45292 | J2: =EDATE(I2,1) -> 45323 | K2: =EDATE(J2,1) -> 45352 | L2: =EDATE(K2,1) -> 45383 | ... CW2: =EDATE(CV2,1) -> 48092
A4: ='Monthly forecast'!A15 -> REVENUE STREAM 1: SELF-SERVICE
A6: Subscription price per month | C6: =IF(C2>=Projections!$D$28,Projections!$B$28,0) -> 0 | D6: =IF(D2>=Projections!$D$28,Projections!$B$28,0) -> 100 | E6: =IF(E2>=Projections!$D$28,Projections!$B$28,0) -> 100 | F6: =IF(F2>=Projections!$D$28,Projections!$B$28,0) -> 100 | G6: =IF(G2>=Projections!$D$28,Projections!$B$28,0) -> 100 | H6: =IF(H2>=Projections!$D$28,Projections!$B$28,0) -> 100 | I6: =IF(I2>=Projections!$D$28,Projections!$B$28,0) -> 100 | J6: =IF(J2>=Projections!$D$28,Projections!$B$28,0) -> 100 | ... CW6: =IF(CW2>=Projections!$D$28,Projections!$B$28,0) -> 100
A7: ARPPU | C7: =C6 -> 0 | D7: =D6 -> 100 | E7: =E6 -> 100 | F7: =F6 -> 100 | G7: =G6 -> 100 | H7: =H6 -> 100 | I7: =I6 -> 100 | J7: =J6 -> 100 | ... CW7: =CW6 -> 100
A9: Churn | C9: ='Monthly forecast'!D18 | D9: ='Monthly forecast'!E18 -> 0.15 | E9: ='Monthly forecast'!F18 -> 0.15 | F9: ='Monthly forecast'!G18 -> 0.15 | G9: ='Monthly forecast'!H18 -> 0.15 | H9: ='Monthly forecast'!I18 -> 0.15 | I9: ='Monthly forecast'!J18 -> 0.15 | J9: ='Monthly forecast'!K18 -> 0.15 | ... CW9: ='Monthly forecast'!CX18 -> 0.15
A10: LT (Ilifetime) | C10: =IFERROR(1/C9,0) -> 0 | D10: =IFERROR(1/D9,0) -> 6.6666667 | E10: =IFERROR(1/E9,0) -> 6.6666667 | F10: =IFERROR(1/F9,0) -> 6.6666667 | G10: =IFERROR(1/G9,0) -> 6.6666667 | H10: =IFERROR(1/H9,0) -> 6.6666667 | I10: =IFERROR(1/I9,0) -> 6.6666667 | J10: =IFERROR(1/J9,0) -> 6.6666667 | ... CW10: =IFERROR(1/CW9,0) -> 6.6666667
A12: LTV | C12: =C7*C10 -> 0 | D12: =D7*D10 -> 666.66667 | E12: =E7*E10 -> 666.66667 | F12: =F7*F10 -> 666.66667 | G12: =G7*G10 -> 666.66667 | H12: =H7*H10 -> 666.66667 | I12: =I7*I10 -> 666.66667 | J12: =J7*J10 -> 666.66667 | ... CW12: =CW7*CW10 -> 666.66667
A13: LTV 3 month | C13: =C7*3 -> 0 | D13: =D7*3 -> 300 | E13: =E7*3 -> 300 | F13: =F7*3 -> 300 | G13: =G7*3 -> 300 | H13: =H7*3 -> 300 | I13: =I7*3 -> 300 | J13: =J7*3 -> 300 | ... CW13: =CW7*3 -> 300
A14: LTV 6 month | C14: =C7*6 -> 0 | D14: =D7*6 -> 600 | E14: =E7*6 -> 600 | F14: =F7*6 -> 600 | G14: =G7*6 -> 600 | H14: =H7*6 -> 600 | I14: =I7*6 -> 600 | J14: =J7*6 -> 600 | ... CW14: =CW7*6 -> 600
A15: LTV 12 month | C15: =C7*12 -> 0 | D15: =D7*12 -> 1200 | E15: =E7*12 -> 1200 | F15: =F7*12 -> 1200 | G15: =G7*12 -> 1200 | H15: =H7*12 -> 1200 | I15: =I7*12 -> 1200 | J15: =J7*12 -> 1200 | ... CW15: =CW7*12 -> 1200
A17: pCAC (CAC paid channels) | D17: ='Monthly forecast'!E10/Projections!$B$36 -> 600 | E17: ='Monthly forecast'!F10/Projections!$B$36 -> 570 | F17: ='Monthly forecast'!G10/Projections!$B$36 -> 541.5 | G17: ='Monthly forecast'!H10/Projections!$B$36 -> 514.425 | H17: ='Monthly forecast'!I10/Projections!$B$36 -> 488.70375 | I17: ='Monthly forecast'!J10/Projections!$B$36 -> 464.26856 | J17: ='Monthly forecast'!K10/Projections!$B$36 -> 441.05513 | K17: ='Monthly forecast'!L10/Projections!$B$36 -> 419.00238 | ... CW17: ='Monthly forecast'!CX10/Projections!$B$36 -> 400
A18: LTV/CAC | D18: =D12/D$17 -> 1.1111111 | E18: =E12/E$17 -> 1.1695906 | F18: =F12/F$17 -> 1.231148 | G18: =G12/G$17 -> 1.2959453 | H18: =H12/H$17 -> 1.364153 | I18: =I12/I$17 -> 1.4359505 | J18: =J12/J$17 -> 1.5115268 | K18: =K12/K$17 -> 1.5910809 | ... CW18: =CW12/CW$17 -> 1.6666667
A19: LTV 3 month/CAC | D19: =D13/D$17 -> 0.5 | E19: =E13/E$17 -> 0.52631579 | F19: =F13/F$17 -> 0.55401662 | G19: =G13/G$17 -> 0.58317539 | H19: =H13/H$17 -> 0.61386883 | I19: =I13/I$17 -> 0.64617772 | J19: =J13/J$17 -> 0.68018707 | K19: =K13/K$17 -> 0.71598639 | ... CW19: =CW13/CW$17 -> 0.75
A20: LTV 6 month/CAC | D20: =D14/D$17 -> 1 | E20: =E14/E$17 -> 1.0526316 | F20: =F14/F$17 -> 1.1080332 | G20: =G14/G$17 -> 1.1663508 | H20: =H14/H$17 -> 1.2277377 | I20: =I14/I$17 -> 1.2923554 | J20: =J14/J$17 -> 1.3603741 | K20: =K14/K$17 -> 1.4319728 | ... CW20: =CW14/CW$17 -> 1.5
A21: LTV 12 month/CAC | D21: =D15/D$17 -> 2 | E21: =E15/E$17 -> 2.1052632 | F21: =F15/F$17 -> 2.2160665 | G21: =G15/G$17 -> 2.3327016 | H21: =H15/H$17 -> 2.4554753 | I21: =I15/I$17 -> 2.5847109 | J21: =J15/J$17 -> 2.7207483 | K21: =K15/K$17 -> 2.8639456 | ... CW21: =CW15/CW$17 -> 3
A24: ='Monthly forecast'!A24 -> REVENUE STREAM 2: INBOUND SALES
A26: Subscription price per month | C26: =IF(C2>=Projections!$D$28,Projections!$B$28,0) -> 0 | D26: =IF(D2>=Projections!$D$28,Projections!$B$28,0) -> 100 | E26: =IF(E2>=Projections!$D$28,Projections!$B$28,0) -> 100 | F26: =IF(F2>=Projections!$D$28,Projections!$B$28,0) -> 100 | G26: =IF(G2>=Projections!$D$28,Projections!$B$28,0) -> 100 | H26: =IF(H2>=Projections!$D$28,Projections!$B$28,0) -> 100 | I26: =IF(I2>=Projections!$D$28,Projections!$B$28,0) -> 100 | J26: =IF(J2>=Projections!$D$28,Projections!$B$28,0) -> 100 | ... CW26: =IF(CW2>=Projections!$D$28,Projections!$B$28,0) -> 100
A27: ARPPU | C27: =C26 -> 0 | D27: =D26 -> 100 | E27: =E26 -> 100 | F27: =F26 -> 100 | G27: =G26 -> 100 | H27: =H26 -> 100 | I27: =I26 -> 100 | J27: =J26 -> 100 | ... CW27: =CW26 -> 100
A29: Churn | C29: ='Monthly forecast'!D38 | D29: ='Monthly forecast'!E29 -> 0.15 | E29: ='Monthly forecast'!F29 -> 0.15 | F29: ='Monthly forecast'!G29 -> 0.15 | G29: ='Monthly forecast'!H29 -> 0.15 | H29: ='Monthly forecast'!I29 -> 0.15 | I29: ='Monthly forecast'!J29 -> 0.15 | J29: ='Monthly forecast'!K29 -> 0.15 | K29: ='Monthly forecast'!L29 -> 0.15 | ... CW29: ='Monthly forecast'!CX29 -> 0.15
A30: LT (Ilifetime) | C30: =IFERROR(1/C29,0) -> 0 | D30: =IFERROR(1/D29,0) -> 6.6666667 | E30: =IFERROR(1/E29,0) -> 6.6666667 | F30: =IFERROR(1/F29,0) -> 6.6666667 | G30: =IFERROR(1/G29,0) -> 6.6666667 | H30: =IFERROR(1/H29,0) -> 6.6666667 | I30: =IFERROR(1/I29,0) -> 6.6666667 | J30: =IFERROR(1/J29,0) -> 6.6666667 | ... CW30: =IFERROR(1/CW29,0) -> 6.6666667
A32: LTV | C32: =C27*C30 -> 0 | D32: =D27*D30 -> 666.66667 | E32: =E27*E30 -> 666.66667 | F32: =F27*F30 -> 666.66667 | G32: =G27*G30 -> 666.66667 | H32: =H27*H30 -> 666.66667 | I32: =I27*I30 -> 666.66667 | J32: =J27*J30 -> 666.66667 | ... CW32: =CW27*CW30 -> 666.66667
A33: LTV 3 month | C33: =C27*3 -> 0 | D33: =D27*3 -> 300 | E33: =E27*3 -> 300 | F33: =F27*3 -> 300 | G33: =G27*3 -> 300 | H33: =H27*3 -> 300 | I33: =I27*3 -> 300 | J33: =J27*3 -> 300 | ... CW33: =CW27*3 -> 300
A34: LTV 6 month | C34: =C27*6 -> 0 | D34: =D27*6 -> 600 | E34: =E27*6 -> 600 | F34: =F27*6 -> 600 | G34: =G27*6 -> 600 | H34: =H27*6 -> 600 | I34: =I27*6 -> 600 | J34: =J27*6 -> 600 | ... CW34: =CW27*6 -> 600
A35: LTV 12 month | C35: =C27*12 -> 0 | D35: =D27*12 -> 1200 | E35: =E27*12 -> 1200 | F35: =F27*12 -> 1200 | G35: =G27*12 -> 1200 | H35: =H27*12 -> 1200 | I35: =I27*12 -> 1200 | J35: =J27*12 -> 1200 | ... CW35: =CW27*12 -> 1200
A37: Marketing Costs | D37: ='Monthly forecast'!E10/Projections!$B$45/Projections!$B$50 -> 300 | E37: ='Monthly forecast'!F10/Projections!$B$45/Projections!$B$50 -> 285 | F37: ='Monthly forecast'!G10/Projections!$B$45/Projections!$B$50 -> 270.75 | G37: ='Monthly forecast'!H10/Projections!$B$45/Projections!$B$50 -> 257.2125 | H37: ='Monthly forecast'!I10/Projections!$B$45/Projections!$B$50 -> 244.35188 | I37: ='Monthly forecast'!J10/Projections!$B$45/Projections!$B$50 -> 232.13428 | J37: ='Monthly forecast'!K10/Projections!$B$45/Projections!$B$50 -> 220.52757 | K37: ='Monthly forecast'!L10/Projections!$B$45/Projections!$B$50 -> 209.50119 | ... CW37: ='Monthly forecast'!CX10/Projections!$B$45/Projections!$B$50 -> 200
A38: Cost of Inbound Sales Managers team | D38: ='Monthly forecast'!E83/(Projections!$B$49*Projections!$B$50) -> 153.84615 | E38: ='Monthly forecast'!F83/(Projections!$B$49*Projections!$B$50) -> 153.84615 | F38: ='Monthly forecast'!G83/(Projections!$B$49*Projections!$B$50) -> 153.84615 | G38: ='Monthly forecast'!H83/(Projections!$B$49*Projections!$B$50) -> 153.84615 | H38: ='Monthly forecast'!I83/(Projections!$B$49*Projections!$B$50) -> 153.84615 | I38: ='Monthly forecast'!J83/(Projections!$B$49*Projections!$B$50) -> 153.84615 | J38: ='Monthly forecast'!K83/(Projections!$B$49*Projections!$B$50) -> 153.84615 | K38: ='Monthly forecast'!L83/(Projections!$B$49*Projections!$B$50) -> 153.84615 | ... CW38: ='Monthly forecast'!CX83/(Projections!$B$49*Projections!$B$50) -> 180.25529
A39: CAC | D39: =D37+D38 -> 453.84615 | E39: =E37+E38 -> 438.84615 | F39: =F37+F38 -> 424.59615 | G39: =G37+G38 -> 411.05865 | H39: =H37+H38 -> 398.19803 | I39: =I37+I38 -> 385.98044 | J39: =J37+J38 -> 374.37372 | K39: =K37+K38 -> 363.34734 | ... CW39: =CW37+CW38 -> 380.25529
A41: LTV/CAC | D41: =D32/D39 -> 1.4689266 | E41: =E32/E39 -> 1.5191353 | F41: =F32/F39 -> 1.5701194 | G41: =G32/G39 -> 1.6218286 | H41: =H32/H39 -> 1.6742089 | I41: =I32/I39 -> 1.7272033 | J41: =J32/J39 -> 1.7807518 | K41: =K32/K39 -> 1.8347916 | ... CV41: =CV32/CV39 -> 1.7532081
A42: LTV 3 month/CAC | D42: =D33/D$39 -> 0.66101695 | E42: =E33/E$39 -> 0.68361087 | F42: =F33/F$39 -> 0.70655374 | G42: =G33/G$39 -> 0.72982285 | H42: =H33/H$39 -> 0.75339399 | I42: =I33/I$39 -> 0.77724147 | J42: =J33/J$39 -> 0.8013383 | K42: =K33/K$39 -> 0.82565624 | ... CW42: =CW33/CW$39 -> 0.78894366
A43: LTV 6 month/CAC | D43: =D34/D$39 -> 1.3220339 | E43: =E34/E$39 -> 1.3672217 | F43: =F34/F$39 -> 1.4131075 | G43: =G34/G$39 -> 1.4596457 | H43: =H34/H$39 -> 1.506788 | I43: =I34/I$39 -> 1.5544829 | J43: =J34/J$39 -> 1.6026766 | K43: =K34/K$39 -> 1.6513125 | ... CW43: =CW34/CW$39 -> 1.5778873
A44: LTV 12 month/CAC | D44: =D35/D$39 -> 2.6440678 | E44: =E35/E$39 -> 2.7344435 | F44: =F35/F$39 -> 2.826215 | G44: =G35/G$39 -> 2.9192914 | H44: =H35/H$39 -> 3.0135759 | I44: =I35/I$39 -> 3.1089659 | J44: =J35/J$39 -> 3.2053532 | K44: =K35/K$39 -> 3.302625 | ... CW44: =CW35/CW$39 -> 3.1557746
A46: ='Monthly forecast'!A35 -> REVENUE STREAM 3: OUTBOUND SALES
A48: Subscription price per month | C48: =IF(C2>=Projections!$D$28,Projections!$B$28,0) -> 0 | D48: =IF(D2>=Projections!$D$28,Projections!$B$28,0) -> 100 | E48: =IF(E2>=Projections!$D$28,Projections!$B$28,0) -> 100 | F48: =IF(F2>=Projections!$D$28,Projections!$B$28,0) -> 100 | G48: =IF(G2>=Projections!$D$28,Projections!$B$28,0) -> 100 | H48: =IF(H2>=Projections!$D$28,Projections!$B$28,0) -> 100 | I48: =IF(I2>=Projections!$D$28,Projections!$B$28,0) -> 100 | J48: =IF(J2>=Projections!$D$28,Projections!$B$28,0) -> 100 | ... CW48: =IF(CW2>=Projections!$D$28,Projections!$B$28,0) -> 100
A49: ARPPU | C49: =C48 -> 0 | D49: =D48 -> 100 | E49: =E48 -> 100 | F49: =F48 -> 100 | G49: =G48 -> 100 | H49: =H48 -> 100 | I49: =I48 -> 100 | J49: =J48 -> 100 | ... CW49: =CW48 -> 100
A51: Churn | C51: ='Monthly forecast'!D60 | D51: ='Monthly forecast'!E38 -> 0.15 | E51: ='Monthly forecast'!F38 -> 0.15 | F51: ='Monthly forecast'!G38 -> 0.15 | G51: ='Monthly forecast'!H38 -> 0.15 | H51: ='Monthly forecast'!I38 -> 0.15 | I51: ='Monthly forecast'!J38 -> 0.15 | J51: ='Monthly forecast'!K38 -> 0.15 | K51: ='Monthly forecast'!L38 -> 0.15 | ... CW51: ='Monthly forecast'!CX38 -> 0.15
